Workbook

Sheet Yhteenveto
B2: KUSTANNUKSET | D2: M€ | H2: Huom.: Vuoden 2023 eurot
B3: Investointikustannukset | D3: =Investointikustannus!X23 -> 0
B4: Rakentamisen aikainen korko | D4: =Investointikustannus!D6-D3 -> 0
B5: Julkisten varojen rajakustannus (verokerroin) | D5: =(Diskonttaus!B10-1)*(Yhteenveto!D3+Yhteenveto!D4) -> 0
B6: Kustannukset yhteensä | D6: =SUM(D3:D5) -> 0 | F6: =MAX(D6,D26) -> #VALUE!
B8: HYÖDYT | D8: M€
B9: Väylänpitäjän kustannusmuutokset
B10: Kunnossapitokustannukset | C10: =-D10 -> 0 | D10: =-(Tuottajahyodyt!L70+Tuottajahyodyt!L90)/1000000 -> 0
B11: Kuluttajan ylijäämä
B12: Aikakustannukset | C12: =-D12 -> 0 | D12: =Kayttajahyodyt!M23/1000000 -> 0
B13: Ajoneuvokustannukset | C13: =-D13 -> 0 | D13: =Kayttajahyodyt!M36/1000000 -> 0
B14: Liput, verot ja maksut | C14: =-D14 -> 0 | D14: =Kayttajahyodyt!M51/1000000 -> 0
B15: Tuottajan ylijäämä
B16: Liikennöintikustannukset | C16: =-D16 -> 0 | D16: =-Tuottajahyodyt!O23/1000000 -> 0
B17: Tulot liikennepalveluista | C17: =-D17 -> 0 | D17: =Tuottajahyodyt!F48/1000000 -> 0
B18: Turvallisuusvaikutukset
B19: Onnettomuuskustannukset | C19: =-D19 -> 0 | D19: =-Ulkoisvaikutukset!C41/1000000 -> 0
B20: Ympäristövaikutukset
B21: Päästökustannukset | C21: =-D21 -> 0 | D21: =-Ulkoisvaikutukset!D41/1000000 -> 0
B22: Melukustannukset | C22: =-D22 -> #VALUE! | D22: =-Ulkoisvaikutukset!E41/1000000 -> #VALUE!
B23: Vaikutukset julkistalouteen
B24: Vero-, maksu- ja muut tulot | C24: =-D24 -> 0 | D24: =Julkistaloudelliset!C16/1000000 -> 0
B25: Investoinnin jäännösarvo | C25: =-D25 -> 0 | D25: =Investointikustannus!AA23 -> 0
B26: Hyödyt yhteensä | C26: =-D26 -> #VALUE! | D26: =SUM(D10:D25) -> #VALUE!
B29: Nettohyöty | D29: =D26-D6 -> #VALUE!
B31: Infrahankkeille
B32: H/Ki | D32: =D26/D6 -> #VALUE!
B34: Liikennöintimuutoksille
B35: H/Kioy | D35: =(SUM(D12:D14)+SUM(D19:D22)+D25)/(D6-D10-SUM(D16:D17)-D24) -> #VALUE!

Sheet Diskonttaus
A1: Nykyhetki | B1: 2023 | E1: Investointi | F1: =B3 -> 2045 | I1: Investointi | J1: =B5 -> 2055 | M1: Hyödyt 1 | R1: Hyödyt 2 | X1: Ajokustannukset 1 | AB1: Ajokustannukset 2 | AE1: Muut kustannukset 1 | AH1: Muut kustannukset 2
A2: Diskonttausvuosi | B2: 2045 | D2: Vuosi | E2: Kustannus | F2: Diskontto | H2: Vuosi | I2: Kustannus | J2: Diskontto | L2: Vuosi | M2: Nimellinen | N2: Reaali | O2: Diskontto | Q2: Vuosi | R2: Nimellinen | S2: Reaali | T2: Diskontto | V2: Vuosi | W2: Nimellinen | X2: Diskontto | Z2: Vuosi | AA2: Nimellinen | AB2: Diskontto | AD2: Vuosi | AE2: Diskontto | AG2: Vuosi | AH2: Diskontto
A3: Avausvuosi 1 | B3: 2045 | D3: =B3-1 -> 2044 | E3: =Investointikustannus!L23 -> 0 | F3: =E3*(1+$B$8)^($B$2-D3) -> 0 | H3: =B5-1 -> 2054 | I3: =Investointikustannus!W23 -> 0 | J3: =I3*(1+$B$8)^($B$2-H3) -> 0 | L3: =B3 -> 2045 | M3: =IF($B$17=0,1,MIN($B$16/$B$15,1+(L3-$B$4)*$B$17)) -> 1 | N3: =M3*(1+$B$9)^(L3-$B$2) -> 1 | O3: =N3/(1+$B$8)^(L3-$B$2) -> 1 | Q3: =B5 -> 2055 | R3: =IF($B$17=0,1,MIN(1,(1+(Q3-$B$4)*$B$17)/($B$16/$B$15))) -> 1 | S3: =R3*(1+$B$9)^(Q3-$B$2) -> 1.1491575 | T3: =S3/(1+$B$8)^(Q3-$B$2) -> 0.81465936 | V3: =B3 -> 2045 | W3: =(1+$B$24)^(L3-$B$4) -> 1 | X3: =W3/(1+$B$8)^(L3-$B$2) -> 1 | Z3: =B5 -> 2055 | AA3: =(1+$B$24)^(Q3-$B$6) -> 1 | AB3: =AA3/(1+$B$8)^(Q3-$B$2) -> 0.70891881 | AD3: =B3 -> 2045 | AE3: =1/(1+$B$8)^(L3-$B$2) -> 1 | AG3: =B5 -> 2055 | AH3: =1/(1+$B$8)^(Q3-$B$2) -> 0.70891881
A4: Ennustevuosi 1 | B4: 2045 | D4: =D3-1 -> 2043 | E4: =Investointikustannus!K23 -> 0 | F4: =E4*(1+$B$8)^($B$2-D4) -> 0 | H4: =H3-1 -> 2053 | I4: =Investointikustannus!V23 -> 0 | J4: =I4*(1+$B$8)^($B$2-H4) -> 0 | L4: =L3+1 -> 2046 | M4: =IF($B$17=0,1,MIN($B$16/$B$15,1+(L4-$B$4)*$B$17)) -> 1 | N4: =M4*(1+$B$9)^(L4-$B$2) -> 1.014 | O4: =N4/(1+$B$8)^(L4-$B$2) -> 0.97971014 | Q4: =Q3+1 -> 2056 | R4: =IF($B$17=0,1,MIN(1,(1+(Q4-$B$4)*$B$17)/($B$16/$B$15))) -> 1 | S4: =R4*(1+$B$9)^(Q4-$B$2) -> 1.1652457 | T4: =S4/(1+$B$8)^(Q4-$B$2) -> 0.79813004 | V4: =V3+1 -> 2046 | W4: =(1+$B$24)^(L4-$B$4) -> 1 | X4: =W4/(1+$B$8)^(L4-$B$2) -> 0.96618357 | Z4: =Z3+1 -> 2056 | AA4: =(1+$B$24)^(Q4-$B$6) -> 1 | AB4: =AA4/(1+$B$8)^(Q4-$B$2) -> 0.68494571 | AD4: =AD3+1 -> 2046 | AE4: =1/(1+$B$8)^(L4-$B$2) -> 0.96618357 | AG4: =AG3+1 -> 2056 | AH4: =1/(1+$B$8)^(Q4-$B$2) -> 0.68494571
A5: Avausvuosi 2 | B5: 2055 | D5: =D4-1 -> 2042 | E5: =Investointikustannus!J23 -> 0 | F5: =E5*(1+$B$8)^($B$2-D5) -> 0 | H5: =H4-1 -> 2052 | I5: =Investointikustannus!U23 -> 0 | J5: =I5*(1+$B$8)^($B$2-H5) -> 0 | L5: =L4+1 -> 2047 | M5: =IF($B$17=0,1,MIN($B$16/$B$15,1+(L5-$B$4)*$B$17)) -> 1 | N5: =M5*(1+$B$9)^(L5-$B$2) -> 1.028196 | O5: =N5/(1+$B$8)^(L5-$B$2) -> 0.95983197 | Q5: =Q4+1 -> 2057 | R5: =IF($B$17=0,1,MIN(1,(1+(Q5-$B$4)*$B$17)/($B$16/$B$15))) -> 1 | S5: =R5*(1+$B$9)^(Q5-$B$2) -> 1.1815591 | T5: =S5/(1+$B$8)^(Q5-$B$2) -> 0.7819361 | V5: =V4+1 -> 2047 | W5: =(1+$B$24)^(L5-$B$4) -> 1 | X5: =W5/(1+$B$8)^(L5-$B$2) -> 0.9335107 | Z5: =Z4+1 -> 2057 | AA5: =(1+$B$24)^(Q5-$B$6) -> 1 | AB5: =AA5/(1+$B$8)^(Q5-$B$2) -> 0.6617833 | AD5: =AD4+1 -> 2047 | AE5: =1/(1+$B$8)^(L5-$B$2) -> 0.9335107 | AG5: =AG4+1 -> 2057 | AH5: =1/(1+$B$8)^(Q5-$B$2) -> 0.6617833
A6: Ennustevuosi 2 | B6: 2060 | D6: =D5-1 -> 2041 | E6: =Investointikustannus!I23 -> 0 | F6: =E6*(1+$B$8)^($B$2-D6) -> 0 | H6: =H5-1 -> 2051 | I6: =Investointikustannus!T23 -> 0 | J6: =I6*(1+$B$8)^($B$2-H6) -> 0 | L6: =L5+1 -> 2048 | M6: =IF($B$17=0,1,MIN($B$16/$B$15,1+(L6-$B$4)*$B$17)) -> 1 | N6: =M6*(1+$B$9)^(L6-$B$2) -> 1.0425907 | O6: =N6/(1+$B$8)^(L6-$B$2) -> 0.94035712 | Q6: =Q5+1 -> 2058 | R6: =IF($B$17=0,1,MIN(1,(1+(Q6-$B$4)*$B$17)/($B$16/$B$15))) -> 1 | S6: =R6*(1+$B$9)^(Q6-$B$2) -> 1.198101 | T6: =S6/(1+$B$8)^(Q6-$B$2) -> 0.76607073 | V6: =V5+1 -> 2048 | W6: =(1+$B$24)^(L6-$B$4) -> 1 | X6: =W6/(1+$B$8)^(L6-$B$2) -> 0.90194271 | Z6: =Z5+1 -> 2058 | AA6: =(1+$B$24)^(Q6-$B$6) -> 1 | AB6: =AA6/(1+$B$8)^(Q6-$B$2) -> 0.63940415 | AD6: =AD5+1 -> 2048 | AE6: =1/(1+$B$8)^(L6-$B$2) -> 0.90194271 | AG6: =AG5+1 -> 2058 | AH6: =1/(1+$B$8)^(Q6-$B$2) -> 0.63940415
A7: Tarkastelujakso [vuotta] | B7: 30 | D7: =D6-1 -> 2040 | E7: =Investointikustannus!H23 -> 0 | F7: =E7*(1+$B$8)^($B$2-D7) -> 0 | H7: =H6-1 -> 2050 | I7: =Investointikustannus!S23 -> 0 | J7: =I7*(1+$B$8)^($B$2-H7) -> 0 | L7: =L6+1 -> 2049 | M7: =IF($B$17=0,1,MIN($B$16/$B$15,1+(L7-$B$4)*$B$17)) -> 1 | N7: =M7*(1+$B$9)^(L7-$B$2) -> 1.057187 | O7: =N7/(1+$B$8)^(L7-$B$2) -> 0.92127741 | Q7: =Q6+1 -> 2059 | R7: =IF($B$17=0,1,MIN(1,(1+(Q7-$B$4)*$B$17)/($B$16/$B$15))) -> 1 | S7: =R7*(1+$B$9)^(Q7-$B$2) -> 1.2148744 | T7: =S7/(1+$B$8)^(Q7-$B$2) -> 0.75052726 | V7: =V6+1 -> 2049 | W7: =(1+$B$24)^(L7-$B$4) -> 1 | X7: =W7/(1+$B$8)^(L7-$B$2) -> 0.87144223 | Z7: =Z6+1 -> 2059 | AA7: =(1+$B$24)^(Q7-$B$6) -> 1 | AB7: =AA7/(1+$B$8)^(Q7-$B$2) -> 0.61778179 | AD7: =AD6+1 -> 2049 | AE7: =1/(1+$B$8)^(L7-$B$2) -> 0.87144223 | AG7: =AG6+1 -> 2059 | AH7: =1/(1+$B$8)^(Q7-$B$2) -> 0.61778179
A8: Laskentakorko | B8: 0.035 | D8: =D7-1 -> 2039 | E8: =Investointikustannus!G23 -> 0 | F8: =E8*(1+$B$8)^($B$2-D8) -> 0 | H8: =H7-1 -> 2049 | I8: =Investointikustannus!R23 -> 0 | J8: =I8*(1+$B$8)^($B$2-H8) -> 0 | L8: =L7+1 -> 2050 | M8: =IF($B$17=0,1,MIN($B$16/$B$15,1+(L8-$B$4)*$B$17)) -> 1 | N8: =M8*(1+$B$9)^(L8-$B$2) -> 1.0719876 | O8: =N8/(1+$B$8)^(L8-$B$2) -> 0.90258482 | Q8: =Q7+1 -> 2060 | R8: =IF($B$17=0,1,MIN(1,(1+(Q8-$B$4)*$B$17)/($B$16/$B$15))) -> 1 | S8: =R8*(1+$B$9)^(Q8-$B$2) -> 1.2318826 | T8: =S8/(1+$B$8)^(Q8-$B$2) -> 0.73529917 | V8: =V7+1 -> 2050 | W8: =(1+$B$24)^(L8-$B$4) -> 1 | X8: =W8/(1+$B$8)^(L8-$B$2) -> 0.84197317 | Z8: =Z7+1 -> 2060 | AA8: =(1+$B$24)^(Q8-$B$6) -> 1 | AB8: =AA8/(1+$B$8)^(Q8-$B$2) -> 0.59689062 | AD8: =AD7+1 -> 2050 | AE8: =1/(1+$B$8)^(L8-$B$2) -> 0.84197317 | AG8: =AG7+1 -> 2060 | AH8: =1/(1+$B$8)^(Q8-$B$2) -> 0.59689062
A9: Yksikköarvojen korko | B9: 0.014 | D9: =D8-1 -> 2038 | E9: =Investointikustannus!F23 -> 0 | F9: =E9*(1+$B$8)^($B$2-D9) -> 0 | H9: =H8-1 -> 2048 | I9: =Investointikustannus!Q23 -> 0 | J9: =I9*(1+$B$8)^($B$2-H9) -> 0 | L9: =L8+1 -> 2051 | M9: =IF($B$17=0,1,MIN($B$16/$B$15,1+(L9-$B$4)*$B$17)) -> 1 | N9: =M9*(1+$B$9)^(L9-$B$2) -> 1.0869955 | O9: =N9/(1+$B$8)^(L9-$B$2) -> 0.88427151 | Q9: =Q8+1 -> 2061 | R9: =IF($B$17=0,1,MIN(1,(1+(Q9-$B$4)*$B$17)/($B$16/$B$15))) -> 1 | S9: =R9*(1+$B$9)^(Q9-$B$2) -> 1.249129 | T9: =S9/(1+$B$8)^(Q9-$B$2) -> 0.72038006 | V9: =V8+1 -> 2051 | W9: =(1+$B$24)^(L9-$B$4) -> 1 | X9: =W9/(1+$B$8)^(L9-$B$2) -> 0.81350064 | Z9: =Z8+1 -> 2061 | AA9: =(1+$B$24)^(Q9-$B$6) -> 1 | AB9: =AA9/(1+$B$8)^(Q9-$B$2) -> 0.57670591 | AD9: =AD8+1 -> 2051 | AE9: =1/(1+$B$8)^(L9-$B$2) -> 0.81350064 | AG9: =AG8+1 -> 2061 | AH9: =1/(1+$B$8)^(Q9-$B$2) -> 0.57670591
A10: Verokerroin | B10: 1.2 | D10: =D9-1 -> 2037 | E10: =Investointikustannus!E23 -> 0 | F10: =E10*(1+$B$8)^($B$2-D10) -> 0 | H10: =H9-1 -> 2047 | I10: =Investointikustannus!P23 -> 0 | J10: =I10*(1+$B$8)^($B$2-H10) -> 0 | L10: =L9+1 -> 2052 | M10: =IF($B$17=0,1,MIN($B$16/$B$15,1+(L10-$B$4)*$B$17)) -> 1 | N10: =M10*(1+$B$9)^(L10-$B$2) -> 1.1022134 | O10: =N10/(1+$B$8)^(L10-$B$2) -> 0.86632977 | Q10: =Q9+1 -> 2062 | R10: =IF($B$17=0,1,MIN(1,(1+(Q10-$B$4)*$B$17)/($B$16/$B$15))) -> 1 | S10: =R10*(1+$B$9)^(Q10-$B$2) -> 1.2666168 | T10: =S10/(1+$B$8)^(Q10-$B$2) -> 0.70576365 | V10: =V9+1 -> 2052 | W10: =(1+$B$24)^(L10-$B$4) -> 1 | X10: =W10/(1+$B$8)^(L10-$B$2) -> 0.78599096 | Z10: =Z9+1 -> 2062 | AA10: =(1+$B$24)^(Q10-$B$6) -> 1 | AB10: =AA10/(1+$B$8)^(Q10-$B$2) -> 0.55720378 | AD10: =AD9+1 -> 2052 | AE10: =1/(1+$B$8)^(L10-$B$2) -> 0.78599096 | AG10: =AG9+1 -> 2062 | AH10: =1/(1+$B$8)^(Q10-$B$2) -> 0.55720378
A11: Vuosilaajennus | B11: 300 | D11: =D10-1 -> 2036 | E11: =Investointikustannus!D23 -> 0 | F11: =E11*(1+$B$8)^($B$2-D11) -> 0 | H11: =H10-1 -> 2046 | I11: =Investointikustannus!O23 -> 0 | J11: =I11*(1+$B$8)^($B$2-H11) -> 0 | L11: =L10+1 -> 2053 | M11: =IF($B$17=0,1,MIN($B$16/$B$15,1+(L11-$B$4)*$B$17)) -> 1 | N11: =M11*(1+$B$9)^(L11-$B$2) -> 1.1176444 | O11: =N11/(1+$B$8)^(L11-$B$2) -> 0.84875206 | Q11: =Q10+1 -> 2063 | R11: =IF($B$17=0,1,MIN(1,(1+(Q11-$B$4)*$B$17)/($B$16/$B$15))) -> 1 | S11: =R11*(1+$B$9)^(Q11-$B$2) -> 1.2843494 | T11: =S11/(1+$B$8)^(Q11-$B$2) -> 0.69144381 | V11: =V10+1 -> 2053 | W11: =(1+$B$24)^(L11-$B$4) -> 1 | X11: =W11/(1+$B$8)^(L11-$B$2) -> 0.75941156 | Z11: =Z10+1 -> 2063 | AA11: =(1+$B$24)^(Q11-$B$6) -> 1 | AB11: =AA11/(1+$B$8)^(Q11-$B$2) -> 0.53836114 | AD11: =AD10+1 -> 2053 | AE11: =1/(1+$B$8)^(L11-$B$2) -> 0.75941156 | AG11: =AG10+1 -> 2063 | AH11: =1/(1+$B$8)^(Q11-$B$2) -> 0.53836114
D12: =D11-1 -> 2035 | E12: =Investointikustannus!C23 -> 0 | F12: =E12*(1+$B$8)^($B$2-D12) -> 0 | H12: =H11-1 -> 2045 | I12: =Investointikustannus!N23 -> 0 | J12: =I12*(1+$B$8)^($B$2-H12) -> 0 | L12: =L11+1 -> 2054 | M12: =IF($B$17=0,1,MIN($B$16/$B$15,1+(L12-$B$4)*$B$17)) -> 1 | N12: =M12*(1+$B$9)^(L12-$B$2) -> 1.1332914 | O12: =N12/(1+$B$8)^(L12-$B$2) -> 0.831531 | Q12: =Q11+1 -> 2064 | R12: =IF($B$17=0,1,MIN(1,(1+(Q12-$B$4)*$B$17)/($B$16/$B$15))) -> 1 | S12: =R12*(1+$B$9)^(Q12-$B$2) -> 1.3023303 | T12: =S12/(1+$B$8)^(Q12-$B$2) -> 0.67741452 | V12: =V11+1 -> 2054 | W12: =(1+$B$24)^(L12-$B$4) -> 1 | X12: =W12/(1+$B$8)^(L12-$B$2) -> 0.73373097 | Z12: =Z11+1 -> 2064 | AA12: =(1+$B$24)^(Q12-$B$6) -> 1 | AB12: =AA12/(1+$B$8)^(Q12-$B$2) -> 0.52015569 | AD12: =AD11+1 -> 2054 | AE12: =1/(1+$B$8)^(L12-$B$2) -> 0.73373097 | AG12: =AG11+1 -> 2064 | AH12: =1/(1+$B$8)^(Q12-$B$2) -> 0.52015569
A13: Nykyhetki-avausvuosi 1 | B13: =((1+B9)^(B3-B1)) -> 1.3577975 | D13: Summa | E13: =SUM(E3:E12) -> 0 | F13: =SUM(F3:F12) -> 0 | H13: Summa | I13: =SUM(I3:I12) -> 0 | J13: =SUM(J3:J12) -> 0 | L13: =L12+1 -> 2055 | M13: =IF($B$17=0,1,MIN($B$16/$B$15,1+(L13-$B$4)*$B$17)) -> 1 | N13: =M13*(1+$B$9)^(L13-$B$2) -> 1.1491575 | O13: =N13/(1+$B$8)^(L13-$B$2) -> 0.81465936 | Q13: =Q12+1 -> 2065 | R13: =IF($B$17=0,1,MIN(1,(1+(Q13-$B$4)*$B$17)/($B$16/$B$15))) -> 1 | S13: =R13*(1+$B$9)^(Q13-$B$2) -> 1.3205629 | T13: =S13/(1+$B$8)^(Q13-$B$2) -> 0.66366987 | V13: =V12+1 -> 2055 | W13: =(1+$B$24)^(L13-$B$4) -> 1 | X13: =W13/(1+$B$8)^(L13-$B$2) -> 0.70891881 | Z13: =Z12+1 -> 2065 | AA13: =(1+$B$24)^(Q13-$B$6) -> 1 | AB13: =AA13/(1+$B$8)^(Q13-$B$2) -> 0.50256588 | AD13: =AD12+1 -> 2055 | AE13: =1/(1+$B$8)^(L13-$B$2) -> 0.70891881 | AG13: =AG12+1 -> 2065 | AH13: =1/(1+$B$8)^(Q13-$B$2) -> 0.50256588
L14: =L13+1 -> 2056 | M14: =IF($B$17=0,1,MIN($B$16/$B$15,1+(L14-$B$4)*$B$17)) -> 1 | N14: =M14*(1+$B$9)^(L14-$B$2) -> 1.1652457 | O14: =N14/(1+$B$8)^(L14-$B$2) -> 0.79813004 | Q14: =Q13+1 -> 2066 | R14: =IF($B$17=0,1,MIN(1,(1+(Q14-$B$4)*$B$17)/($B$16/$B$15))) -> 1 | S14: =R14*(1+$B$9)^(Q14-$B$2) -> 1.3390508 | T14: =S14/(1+$B$8)^(Q14-$B$2) -> 0.65020411 | V14: =V13+1 -> 2056 | W14: =(1+$B$24)^(L14-$B$4) -> 1 | X14: =W14/(1+$B$8)^(L14-$B$2) -> 0.68494571 | Z14: =Z13+1 -> 2066 | AA14: =(1+$B$24)^(Q14-$B$6) -> 1 | AB14: =AA14/(1+$B$8)^(Q14-$B$2) -> 0.4855709 | AD14: =AD13+1 -> 2056 | AE14: =1/(1+$B$8)^(L14-$B$2) -> 0.68494571 | AG14: =AG13+1 -> 2066 | AH14: =1/(1+$B$8)^(Q14-$B$2) -> 0.4855709
A15: Hyötyindeksi ev 1 | B15: 100 | L15: =L14+1 -> 2057 | M15: =IF($B$17=0,1,MIN($B$16/$B$15,1+(L15-$B$4)*$B$17)) -> 1 | N15: =M15*(1+$B$9)^(L15-$B$2) -> 1.1815591 | O15: =N15/(1+$B$8)^(L15-$B$2) -> 0.7819361 | Q15: =Q14+1 -> 2067 | R15: =IF($B$17=0,1,MIN(1,(1+(Q15-$B$4)*$B$17)/($B$16/$B$15))) -> 1 | S15: =R15*(1+$B$9)^(Q15-$B$2) -> 1.3577975 | T15: =S15/(1+$B$8)^(Q15-$B$2) -> 0.63701156 | V15: =V14+1 -> 2057 | W15: =(1+$B$24)^(L15-$B$4) -> 1 | X15: =W15/(1+$B$8)^(L15-$B$2) -> 0.6617833 | Z15: =Z14+1 -> 2067 | AA15: =(1+$B$24)^(Q15-$B$6) -> 1 | AB15: =AA15/(1+$B$8)^(Q15-$B$2) -> 0.46915063 | AD15: =AD14+1 -> 2057 | AE15: =1/(1+$B$8)^(L15-$B$2) -> 0.6617833 | AG15: =AG14+1 -> 2067 | AH15: =1/(1+$B$8)^(Q15-$B$2) -> 0.46915063
A16: Hyötyindeksi ev 2 | B16: =IF(Kayttajahyodyt!M21=0,"Ennuste 2 puuttuu",Kayttajahyodyt!M21/Kayttajahyodyt!M16*100) -> Ennuste 2 puuttuu | L16: =L15+1 -> 2058 | M16: =IF($B$17=0,1,MIN($B$16/$B$15,1+(L16-$B$4)*$B$17)) -> 1 | N16: =M16*(1+$B$9)^(L16-$B$2) -> 1.198101 | O16: =N16/(1+$B$8)^(L16-$B$2) -> 0.76607073 | Q16: =Q15+1 -> 2068 | R16: =IF($B$17=0,1,MIN(1,(1+(Q16-$B$4)*$B$17)/($B$16/$B$15))) -> 1 | S16: =R16*(1+$B$9)^(Q16-$B$2) -> 1.3768067 | T16: =S16/(1+$B$8)^(Q16-$B$2) -> 0.62408669 | V16: =V15+1 -> 2058 | W16: =(1+$B$24)^(L16-$B$4) -> 1 | X16: =W16/(1+$B$8)^(L16-$B$2) -> 0.63940415 | Z16: =Z15+1 -> 2068 | AA16: =(1+$B$24)^(Q16-$B$6) -> 1 | AB16: =AA16/(1+$B$8)^(Q16-$B$2) -> 0.45328563 | AD16: =AD15+1 -> 2058 | AE16: =1/(1+$B$8)^(L16-$B$2) -> 0.63940415 | AG16: =AG15+1 -> 2068 | AH16: =1/(1+$B$8)^(Q16-$B$2) -> 0.45328563
A17: Hyötyjen kasvu | B17: =IF(AND(ISNUMBER(B6),B6>B4,ISNUMBER(B16)),(B16/B15-1)/(B6-B4),0) -> 0 | L17: =L16+1 -> 2059 | M17: =IF($B$17=0,1,MIN($B$16/$B$15,1+(L17-$B$4)*$B$17)) -> 1 | N17: =M17*(1+$B$9)^(L17-$B$2) -> 1.2148744 | O17: =N17/(1+$B$8)^(L17-$B$2) -> 0.75052726 | Q17: =Q16+1 -> 2069 | R17: =IF($B$17=0,1,MIN(1,(1+(Q17-$B$4)*$B$17)/($B$16/$B$15))) -> 1 | S17: =R17*(1+$B$9)^(Q17-$B$2) -> 1.396082 | T17: =S17/(1+$B$8)^(Q17-$B$2) -> 0.61142406 | V17: =V16+1 -> 2059 | W17: =(1+$B$24)^(L17-$B$4) -> 1 | X17: =W17/(1+$B$8)^(L17-$B$2) -> 0.61778179 | Z17: =Z16+1 -> 2069 | AA17: =(1+$B$24)^(Q17-$B$6) -> 1 | AB17: =AA17/(1+$B$8)^(Q17-$B$2) -> 0.43795713 | AD17: =AD16+1 -> 2059 | AE17: =1/(1+$B$8)^(L17-$B$2) -> 0.61778179 | AG17: =AG16+1 -> 2069 | AH17: =1/(1+$B$8)^(Q17-$B$2) -> 0.43795713
L18: =L17+1 -> 2060 | M18: =IF($B$17=0,1,MIN($B$16/$B$15,1+(L18-$B$4)*$B$17)) -> 1 | N18: =M18*(1+$B$9)^(L18-$B$2) -> 1.2318826 | O18: =N18/(1+$B$8)^(L18-$B$2) -> 0.73529917 | Q18: =Q17+1 -> 2070 | R18: =IF($B$17=0,1,MIN(1,(1+(Q18-$B$4)*$B$17)/($B$16/$B$15))) -> 1 | S18: =R18*(1+$B$9)^(Q18-$B$2) -> 1.4156271 | T18: =S18/(1+$B$8)^(Q18-$B$2) -> 0.59901835 | V18: =V17+1 -> 2060 | W18: =(1+$B$24)^(L18-$B$4) -> 1 | X18: =W18/(1+$B$8)^(L18-$B$2) -> 0.59689062 | Z18: =Z17+1 -> 2070 | AA18: =(1+$B$24)^(Q18-$B$6) -> 1 | AB18: =AA18/(1+$B$8)^(Q18-$B$2) -> 0.42314699 | AD18: =AD17+1 -> 2060 | AE18: =1/(1+$B$8)^(L18-$B$2) -> 0.59689062 | AG18: =AG17+1 -> 2070 | AH18: =1/(1+$B$8)^(Q18-$B$2) -> 0.42314699
A19: Hyötykerroin ennuste 1 | B19: =IF(OR(B5>B3+B7,NOT(ISNUMBER(B5)),NOT(ISNUMBER(B16))),SUM(OFFSET(O3,0,0,B7)),IF(B5-B3<=0,"Avausvuosi 2 tulee olla ensimmäisen avausvuoden jälkeen",SUM(OFFSET(O3,0,0,B5-B3)))) -> 22.63866 | L19: =L18+1 -> 2061 | M19: =IF($B$17=0,1,MIN($B$16/$B$15,1+(L19-$B$4)*$B$17)) -> 1 | N19: =M19*(1+$B$9)^(L19-$B$2) -> 1.249129 | O19: =N19/(1+$B$8)^(L19-$B$2) -> 0.72038006 | Q19: =Q18+1 -> 2071 | R19: =IF($B$17=0,1,MIN(1,(1+(Q19-$B$4)*$B$17)/($B$16/$B$15))) -> 1 | S19: =R19*(1+$B$9)^(Q19-$B$2) -> 1.4354459 | T19: =S19/(1+$B$8)^(Q19-$B$2) -> 0.58686436 | V19: =V18+1 -> 2061 | W19: =(1+$B$24)^(L19-$B$4) -> 1 | X19: =W19/(1+$B$8)^(L19-$B$2) -> 0.57670591 | Z19: =Z18+1 -> 2071 | AA19: =(1+$B$24)^(Q19-$B$6) -> 1 | AB19: =AA19/(1+$B$8)^(Q19-$B$2) -> 0.40883767 | AD19: =AD18+1 -> 2061 | AE19: =1/(1+$B$8)^(L19-$B$2) -> 0.57670591 | AG19: =AG18+1 -> 2071 | AH19: =1/(1+$B$8)^(Q19-$B$2) -> 0.40883767
A20: Hyötykerroin ennuste 2 | B20: =IF(AND(ISNUMBER(B5),ISNUMBER(B16)),IF(B5-B3<=0,"Avausvuosi 2 tulee olla ensimmäisen avausvuoden jälkeen",IF(B5-B3>=B7,"Avausvuosi 2 ei ole tarkastelujakson sisällä",SUM(OFFSET(T3,0,0,B7-(B5-B3))))),"Ennuste/avausvuosi 2 puuttuu") -> Ennuste/avausvuosi 2 puuttuu | L20: =L19+1 -> 2062 | M20: =IF($B$17=0,1,MIN($B$16/$B$15,1+(L20-$B$4)*$B$17)) -> 1 | N20: =M20*(1+$B$9)^(L20-$B$2) -> 1.2666168 | O20: =N20/(1+$B$8)^(L20-$B$2) -> 0.70576365 | Q20: =Q19+1 -> 2072 | R20: =IF($B$17=0,1,MIN(1,(1+(Q20-$B$4)*$B$17)/($B$16/$B$15))) -> 1 | S20: =R20*(1+$B$9)^(Q20-$B$2) -> 1.4555421 | T20: =S20/(1+$B$8)^(Q20-$B$2) -> 0.57495697 | V20: =V19+1 -> 2062 | W20: =(1+$B$24)^(L20-$B$4) -> 1 | X20: =W20/(1+$B$8)^(L20-$B$2) -> 0.55720378 | Z20: =Z19+1 -> 2072 | AA20: =(1+$B$24)^(Q20-$B$6) -> 1 | AB20: =AA20/(1+$B$8)^(Q20-$B$2) -> 0.39501224 | AD20: =AD19+1 -> 2062 | AE20: =1/(1+$B$8)^(L20-$B$2) -> 0.55720378 | AG20: =AG19+1 -> 2072 | AH20: =1/(1+$B$8)^(Q20-$B$2) -> 0.39501224
L21: =L20+1 -> 2063 | M21: =IF($B$17=0,1,MIN($B$16/$B$15,1+(L21-$B$4)*$B$17)) -> 1 | N21: =M21*(1+$B$9)^(L21-$B$2) -> 1.2843494 | O21: =N21/(1+$B$8)^(L21-$B$2) -> 0.69144381 | Q21: =Q20+1 -> 2073 | R21: =IF($B$17=0,1,MIN(1,(1+(Q21-$B$4)*$B$17)/($B$16/$B$15))) -> 1 | S21: =R21*(1+$B$9)^(Q21-$B$2) -> 1.4759197 | T21: =S21/(1+$B$8)^(Q21-$B$2) -> 0.56329117 | V21: =V20+1 -> 2063 | W21: =(1+$B$24)^(L21-$B$4) -> 1 | X21: =W21/(1+$B$8)^(L21-$B$2) -> 0.53836114 | Z21: =Z20+1 -> 2073 | AA21: =(1+$B$24)^(Q21-$B$6) -> 1 | AB21: =AA21/(1+$B$8)^(Q21-$B$2) -> 0.38165434 | AD21: =AD20+1 -> 2063 | AE21: =1/(1+$B$8)^(L21-$B$2) -> 0.53836114 | AG21: =AG20+1 -> 2073 | AH21: =1/(1+$B$8)^(Q21-$B$2) -> 0.38165434
A22: Ajokustannusindeksi ev 1 | B22: 100 | L22: =L21+1 -> 2064 | M22: =IF($B$17=0,1,MIN($B$16/$B$15,1+(L22-$B$4)*$B$17)) -> 1 | N22: =M22*(1+$B$9)^(L22-$B$2) -> 1.3023303 | O22: =N22/(1+$B$8)^(L22-$B$2) -> 0.67741452 | Q22: =Q21+1 -> 2074 | R22: =IF($B$17=0,1,MIN(1,(1+(Q22-$B$4)*$B$17)/($B$16/$B$15))) -> 1 | S22: =R22*(1+$B$9)^(Q22-$B$2) -> 1.4965826 | T22: =S22/(1+$B$8)^(Q22-$B$2) -> 0.55186208 | V22: =V21+1 -> 2064 | W22: =(1+$B$24)^(L22-$B$4) -> 1 | X22: =W22/(1+$B$8)^(L22-$B$2) -> 0.52015569 | Z22: =Z21+1 -> 2074 | AA22: =(1+$B$24)^(Q22-$B$6) -> 1 | AB22: =AA22/(1+$B$8)^(Q22-$B$2) -> 0.36874815 | AD22: =AD21+1 -> 2064 | AE22: =1/(1+$B$8)^(L22-$B$2) -> 0.52015569 | AG22: =AG21+1 -> 2074 | AH22: =1/(1+$B$8)^(Q22-$B$2) -> 0.36874815
A23: Ajokustannusindeksi ev 2 | B23: =IF(Tuottajahyodyt!L68=0,"Ennuste 2 puuttuu",(Kayttajahyodyt!M34+Kayttajahyodyt!M49+Tuottajahyodyt!F46-Tuottajahyodyt!L68-Julkistaloudelliset!C14)/(Kayttajahyodyt!M29+Kayttajahyodyt!M44+Tuottajahyodyt!F43-Tuottajahyodyt!L60-Julkistaloudelliset!C9)*100) -> Ennuste 2 puuttuu | L23: =L22+1 -> 2065 | M23: =IF($B$17=0,1,MIN($B$16/$B$15,1+(L23-$B$4)*$B$17)) -> 1 | N23: =M23*(1+$B$9)^(L23-$B$2) -> 1.3205629 | O23: =N23/(1+$B$8)^(L23-$B$2) -> 0.66366987 | Q23: =Q22+1 -> 2075 | R23: =IF($B$17=0,1,MIN(1,(1+(Q23-$B$4)*$B$17)/($B$16/$B$15))) -> 1 | S23: =R23*(1+$B$9)^(Q23-$B$2) -> 1.5175348 | T23: =S23/(1+$B$8)^(Q23-$B$2) -> 0.54066488 | V23: =V22+1 -> 2065 | W23: =(1+$B$24)^(L23-$B$4) -> 1 | X23: =W23/(1+$B$8)^(L23-$B$2) -> 0.50256588 | Z23: =Z22+1 -> 2075 | AA23: =(1+$B$24)^(Q23-$B$6) -> 1 | AB23: =AA23/(1+$B$8)^(Q23-$B$2) -> 0.35627841 | AD23: =AD22+1 -> 2065 | AE23: =1/(1+$B$8)^(L23-$B$2) -> 0.50256588 | AG23: =AG22+1 -> 2075 | AH23: =1/(1+$B$8)^(Q23-$B$2) -> 0.35627841
A24: Kustannusten kasvu | B24: =IF(AND(ISNUMBER(B6),B6>B4,ISNUMBER(B23)),_xlfn.RRI(B6-B4,B22,B23),0) -> 0 | L24: =L23+1 -> 2066 | M24: =IF($B$17=0,1,MIN($B$16/$B$15,1+(L24-$B$4)*$B$17)) -> 1 | N24: =M24*(1+$B$9)^(L24-$B$2) -> 1.3390508 | O24: =N24/(1+$B$8)^(L24-$B$2) -> 0.65020411 | Q24: =Q23+1 -> 2076 | R24: =IF($B$17=0,1,MIN(1,(1+(Q24-$B$4)*$B$17)/($B$16/$B$15))) -> 1 | S24: =R24*(1+$B$9)^(Q24-$B$2) -> 1.5387803 | T24: =S24/(1+$B$8)^(Q24-$B$2) -> 0.52969486 | V24: =V23+1 -> 2066 | W24: =(1+$B$24)^(L24-$B$4) -> 1 | X24: =W24/(1+$B$8)^(L24-$B$2) -> 0.4855709 | Z24: =Z23+1 -> 2076 | AA24: =(1+$B$24)^(Q24-$B$6) -> 1 | AB24: =AA24/(1+$B$8)^(Q24-$B$2) -> 0.34423035 | AD24: =AD23+1 -> 2066 | AE24: =1/(1+$B$8)^(L24-$B$2) -> 0.4855709 | AG24: =AG23+1 -> 2076 | AH24: =1/(1+$B$8)^(Q24-$B$2) -> 0.34423035
L25: =L24+1 -> 2067 | M25: =IF($B$17=0,1,MIN($B$16/$B$15,1+(L25-$B$4)*$B$17)) -> 1 | N25: =M25*(1+$B$9)^(L25-$B$2) -> 1.3577975 | O25: =N25/(1+$B$8)^(L25-$B$2) -> 0.63701156 | Q25: =Q24+1 -> 2077 | R25: =IF($B$17=0,1,MIN(1,(1+(Q25-$B$4)*$B$17)/($B$16/$B$15))) -> 1 | S25: =R25*(1+$B$9)^(Q25-$B$2) -> 1.5603232 | T25: =S25/(1+$B$8)^(Q25-$B$2) -> 0.51894743 | V25: =V24+1 -> 2067 | W25: =(1+$B$24)^(L25-$B$4) -> 1 | X25: =W25/(1+$B$8)^(L25-$B$2) -> 0.46915063 | Z25: =Z24+1 -> 2077 | AA25: =(1+$B$24)^(Q25-$B$6) -> 1 | AB25: =AA25/(1+$B$8)^(Q25-$B$2) -> 0.33258971 | AD25: =AD24+1 -> 2067 | AE25: =1/(1+$B$8)^(L25-$B$2) -> 0.46915063 | AG25: =AG24+1 -> 2077 | AH25: =1/(1+$B$8)^(Q25-$B$2) -> 0.33258971
A26: Ajokustannuskerroin 1 | B26: =IF(OR(B5>B3+B7,NOT(ISNUMBER(B5)),NOT(ISNUMBER(B16))),SUM(OFFSET(X3,0,0,B7)),IF(B5-B3<=0,"Avausvuosi 2 tulee olla ensimmäisen avausvuoden jälkeen",SUM(OFFSET(X3,0,0,B5-B3)))) -> 19.035767 | L26: =L25+1 -> 2068 | M26: =IF($B$17=0,1,MIN($B$16/$B$15,1+(L26-$B$4)*$B$17)) -> 1 | N26: =M26*(1+$B$9)^(L26-$B$2) -> 1.3768067 | O26: =N26/(1+$B$8)^(L26-$B$2) -> 0.62408669 | Q26: =Q25+1 -> 2078 | R26: =IF($B$17=0,1,MIN(1,(1+(Q26-$B$4)*$B$17)/($B$16/$B$15))) -> 1 | S26: =R26*(1+$B$9)^(Q26-$B$2) -> 1.5821677 | T26: =S26/(1+$B$8)^(Q26-$B$2) -> 0.50841806 | V26: =V25+1 -> 2068 | W26: =(1+$B$24)^(L26-$B$4) -> 1 | X26: =W26/(1+$B$8)^(L26-$B$2) -> 0.45328563 | Z26: =Z25+1 -> 2078 | AA26: =(1+$B$24)^(Q26-$B$6) -> 1 | AB26: =AA26/(1+$B$8)^(Q26-$B$2) -> 0.32134271 | AD26: =AD25+1 -> 2068 | AE26: =1/(1+$B$8)^(L26-$B$2) -> 0.45328563 | AG26: =AG25+1 -> 2078 | AH26: =1/(1+$B$8)^(Q26-$B$2) -> 0.32134271
A27: Ajokustannuskerroin 2 | B27: =IF(AND(ISNUMBER(B5),ISNUMBER(B16)),IF(B5-B3<=0,"Avausvuosi 2 tulee olla ensimmäisen avausvuoden jälkeen",IF(B5-B3>=B7,"Avausvuosi 2 ei ole tarkastelujakson sisällä",SUM(OFFSET(AB3,0,0,B7-(B5-B3))))),"Ennuste/avausvuosi 2 puuttuu") -> Ennuste/avausvuosi 2 puuttuu | L27: =L26+1 -> 2069 | M27: =IF($B$17=0,1,MIN($B$16/$B$15,1+(L27-$B$4)*$B$17)) -> 1 | N27: =M27*(1+$B$9)^(L27-$B$2) -> 1.396082 | O27: =N27/(1+$B$8)^(L27-$B$2) -> 0.61142406 | Q27: =Q26+1 -> 2079 | R27: =IF($B$17=0,1,MIN(1,(1+(Q27-$B$4)*$B$17)/($B$16/$B$15))) -> 1 | S27: =R27*(1+$B$9)^(Q27-$B$2) -> 1.6043181 | T27: =S27/(1+$B$8)^(Q27-$B$2) -> 0.49810233 | V27: =V26+1 -> 2069 | W27: =(1+$B$24)^(L27-$B$4) -> 1 | X27: =W27/(1+$B$8)^(L27-$B$2) -> 0.43795713 | Z27: =Z26+1 -> 2079 | AA27: =(1+$B$24)^(Q27-$B$6) -> 1 | AB27: =AA27/(1+$B$8)^(Q27-$B$2) -> 0.31047605 | AD27: =AD26+1 -> 2069 | AE27: =1/(1+$B$8)^(L27-$B$2) -> 0.43795713 | AG27: =AG26+1 -> 2079 | AH27: =1/(1+$B$8)^(Q27-$B$2) -> 0.31047605
L28: =L27+1 -> 2070 | M28: =IF($B$17=0,1,MIN($B$16/$B$15,1+(L28-$B$4)*$B$17)) -> 1 | N28: =M28*(1+$B$9)^(L28-$B$2) -> 1.4156271 | O28: =N28/(1+$B$8)^(L28-$B$2) -> 0.59901835 | Q28: =Q27+1 -> 2080 | R28: =IF($B$17=0,1,MIN(1,(1+(Q28-$B$4)*$B$17)/($B$16/$B$15))) -> 1 | S28: =R28*(1+$B$9)^(Q28-$B$2) -> 1.6267785 | T28: =S28/(1+$B$8)^(Q28-$B$2) -> 0.48799591 | V28: =V27+1 -> 2070 | W28: =(1+$B$24)^(L28-$B$4) -> 1 | X28: =W28/(1+$B$8)^(L28-$B$2) -> 0.42314699 | Z28: =Z27+1 -> 2080 | AA28: =(1+$B$24)^(Q28-$B$6) -> 1 | AB28: =AA28/(1+$B$8)^(Q28-$B$2) -> 0.29997686 | AD28: =AD27+1 -> 2070 | AE28: =1/(1+$B$8)^(L28-$B$2) -> 0.42314699 | AG28: =AG27+1 -> 2080 | AH28: =1/(1+$B$8)^(Q28-$B$2) -> 0.29997686
A29: Muu kustannuskerroin 1 | B29: =IF(OR(B5>B3+B7,NOT(ISNUMBER(B5)),NOT(ISNUMBER(B16))),SUM(OFFSET(AE3,0,0,B7)),IF(B5-B3<=0,"Avausvuosi 2 tulee olla ensimmäisen avausvuoden jälkeen",SUM(OFFSET(AE3,0,0,B5-B3)))) -> 19.035767 | L29: =L28+1 -> 2071 | M29: =IF($B$17=0,1,MIN($B$16/$B$15,1+(L29-$B$4)*$B$17)) -> 1 | N29: =M29*(1+$B$9)^(L29-$B$2) -> 1.4354459 | O29: =N29/(1+$B$8)^(L29-$B$2) -> 0.58686436 | Q29: =Q28+1 -> 2081 | R29: =IF($B$17=0,1,MIN(1,(1+(Q29-$B$4)*$B$17)/($B$16/$B$15))) -> 1 | S29: =R29*(1+$B$9)^(Q29-$B$2) -> 1.6495534 | T29: =S29/(1+$B$8)^(Q29-$B$2) -> 0.47809454 | V29: =V28+1 -> 2071 | W29: =(1+$B$24)^(L29-$B$4) -> 1 | X29: =W29/(1+$B$8)^(L29-$B$2) -> 0.40883767 | Z29: =Z28+1 -> 2081 | AA29: =(1+$B$24)^(Q29-$B$6) -> 1 | AB29: =AA29/(1+$B$8)^(Q29-$B$2) -> 0.28983272 | AD29: =AD28+1 -> 2071 | AE29: =1/(1+$B$8)^(L29-$B$2) -> 0.40883767 | AG29: =AG28+1 -> 2081 | AH29: =1/(1+$B$8)^(Q29-$B$2) -> 0.28983272
A30: Muu kustannuskerroin 2 | B30: =IF(AND(ISNUMBER(B5),ISNUMBER(B16)),IF(B5-B3<=0,"Avausvuosi 2 tulee olla ensimmäisen avausvuoden jälkeen",IF(B5-B3>=B7,"Avausvuosi 2 ei ole tarkastelujakson sisällä",SUM(OFFSET(AH3,0,0,B7-(B5-B3))))),"Ennuste/avausvuosi 2 puuttuu") -> Ennuste/avausvuosi 2 puuttuu | L30: =L29+1 -> 2072 | M30: =IF($B$17=0,1,MIN($B$16/$B$15,1+(L30-$B$4)*$B$17)) -> 1 | N30: =M30*(1+$B$9)^(L30-$B$2) -> 1.4555421 | O30: =N30/(1+$B$8)^(L30-$B$2) -> 0.57495697 | Q30: =Q29+1 -> 2082 | R30: =IF($B$17=0,1,MIN(1,(1+(Q30-$B$4)*$B$17)/($B$16/$B$15))) -> 1 | S30: =R30*(1+$B$9)^(Q30-$B$2) -> 1.6726472 | T30: =S30/(1+$B$8)^(Q30-$B$2) -> 0.46839407 | V30: =V29+1 -> 2072 | W30: =(1+$B$24)^(L30-$B$4) -> 1 | X30: =W30/(1+$B$8)^(L30-$B$2) -> 0.39501224 | Z30: =Z29+1 -> 2082 | AA30: =(1+$B$24)^(Q30-$B$6) -> 1 | AB30: =AA30/(1+$B$8)^(Q30-$B$2) -> 0.28003161 | AD30: =AD29+1 -> 2072 | AE30: =1/(1+$B$8)^(L30-$B$2) -> 0.39501224 | AG30: =AG29+1 -> 2082 | AH30: =1/(1+$B$8)^(Q30-$B$2) -> 0.28003161
L31: =L30+1 -> 2073 | M31: =IF($B$17=0,1,MIN($B$16/$B$15,1+(L31-$B$4)*$B$17)) -> 1 | N31: =M31*(1+$B$9)^(L31-$B$2) -> 1.4759197 | O31: =N31/(1+$B$8)^(L31-$B$2) -> 0.56329117 | Q31: =Q30+1 -> 2083 | R31: =IF($B$17=0,1,MIN(1,(1+(Q31-$B$4)*$B$17)/($B$16/$B$15))) -> 1 | S31: =R31*(1+$B$9)^(Q31-$B$2) -> 1.6960642 | T31: =S31/(1+$B$8)^(Q31-$B$2) -> 0.45889043 | V31: =V30+1 -> 2073 | W31: =(1+$B$24)^(L31-$B$4) -> 1 | X31: =W31/(1+$B$8)^(L31-$B$2) -> 0.38165434 | Z31: =Z30+1 -> 2083 | AA31: =(1+$B$24)^(Q31-$B$6) -> 1 | AB31: =AA31/(1+$B$8)^(Q31-$B$2) -> 0.27056194 | AD31: =AD30+1 -> 2073 | AE31: =1/(1+$B$8)^(L31-$B$2) -> 0.38165434 | AG31: =AG30+1 -> 2083 | AH31: =1/(1+$B$8)^(Q31-$B$2) -> 0.27056194
L32: =L31+1 -> 2074 | M32: =IF($B$17=0,1,MIN($B$16/$B$15,1+(L32-$B$4)*$B$17)) -> 1 | N32: =M32*(1+$B$9)^(L32-$B$2) -> 1.4965826 | O32: =N32/(1+$B$8)^(L32-$B$2) -> 0.55186208 | Q32: =Q31+1 -> 2084 | R32: =IF($B$17=0,1,MIN(1,(1+(Q32-$B$4)*$B$17)/($B$16/$B$15))) -> 1 | S32: =R32*(1+$B$9)^(Q32-$B$2) -> 1.7198091 | T32: =S32/(1+$B$8)^(Q32-$B$2) -> 0.44957961 | V32: =V31+1 -> 2074 | W32: =(1+$B$24)^(L32-$B$4) -> 1 | X32: =W32/(1+$B$8)^(L32-$B$2) -> 0.36874815 | Z32: =Z31+1 -> 2084 | AA32: =(1+$B$24)^(Q32-$B$6) -> 1 | AB32: =AA32/(1+$B$8)^(Q32-$B$2) -> 0.2614125 | AD32: =AD31+1 -> 2074 | AE32: =1/(1+$B$8)^(L32-$B$2) -> 0.36874815 | AG32: =AG31+1 -> 2084 | AH32: =1/(1+$B$8)^(Q32-$B$2) -> 0.2614125
L33: =L32+1 -> 2075 | M33: =IF($B$17=0,1,MIN($B$16/$B$15,1+(L33-$B$4)*$B$17)) -> 1 | N33: =M33*(1+$B$9)^(L33-$B$2) -> 1.5175348 | O33: =N33/(1+$B$8)^(L33-$B$2) -> 0.54066488 | Q33: =Q32+1 -> 2085 | R33: =IF($B$17=0,1,MIN(1,(1+(Q33-$B$4)*$B$17)/($B$16/$B$15))) -> 1 | S33: =R33*(1+$B$9)^(Q33-$B$2) -> 1.7438864 | T33: =S33/(1+$B$8)^(Q33-$B$2) -> 0.4404577 | V33: =V32+1 -> 2075 | W33: =(1+$B$24)^(L33-$B$4) -> 1 | X33: =W33/(1+$B$8)^(L33-$B$2) -> 0.35627841 | Z33: =Z32+1 -> 2085 | AA33: =(1+$B$24)^(Q33-$B$6) -> 1 | AB33: =AA33/(1+$B$8)^(Q33-$B$2) -> 0.25257247 | AD33: =AD32+1 -> 2075 | AE33: =1/(1+$B$8)^(L33-$B$2) -> 0.35627841 | AG33: =AG32+1 -> 2085 | AH33: =1/(1+$B$8)^(Q33-$B$2) -> 0.25257247
L34: =L33+1 -> 2076 | M34: =IF($B$17=0,1,MIN($B$16/$B$15,1+(L34-$B$4)*$B$17)) -> 1 | N34: =M34*(1+$B$9)^(L34-$B$2) -> 1.5387803 | O34: =N34/(1+$B$8)^(L34-$B$2) -> 0.52969486 | Q34: =Q33+1 -> 2086 | R34: =IF($B$17=0,1,MIN(1,(1+(Q34-$B$4)*$B$17)/($B$16/$B$15))) -> 1 | S34: =R34*(1+$B$9)^(Q34-$B$2) -> 1.7683008 | T34: =S34/(1+$B$8)^(Q34-$B$2) -> 0.43152088 | V34: =V33+1 -> 2076 | W34: =(1+$B$24)^(L34-$B$4) -> 1 | X34: =W34/(1+$B$8)^(L34-$B$2) -> 0.34423035 | Z34: =Z33+1 -> 2086 | AA34: =(1+$B$24)^(Q34-$B$6) -> 1 | AB34: =AA34/(1+$B$8)^(Q34-$B$2) -> 0.24403137 | AD34: =AD33+1 -> 2076 | AE34: =1/(1+$B$8)^(L34-$B$2) -> 0.34423035 | AG34: =AG33+1 -> 2086 | AH34: =1/(1+$B$8)^(Q34-$B$2) -> 0.24403137
L35: =L34+1 -> 2077 | M35: =IF($B$17=0,1,MIN($B$16/$B$15,1+(L35-$B$4)*$B$17)) -> 1 | N35: =M35*(1+$B$9)^(L35-$B$2) -> 1.5603232 | O35: =N35/(1+$B$8)^(L35-$B$2) -> 0.51894743 | Q35: =Q34+1 -> 2087 | R35: =IF($B$17=0,1,MIN(1,(1+(Q35-$B$4)*$B$17)/($B$16/$B$15))) -> 1 | S35: =R35*(1+$B$9)^(Q35-$B$2) -> 1.7930571 | T35: =S35/(1+$B$8)^(Q35-$B$2) -> 0.42276538 | V35: =V34+1 -> 2077 | W35: =(1+$B$24)^(L35-$B$4) -> 1 | X35: =W35/(1+$B$8)^(L35-$B$2) -> 0.33258971 | Z35: =Z34+1 -> 2087 | AA35: =(1+$B$24)^(Q35-$B$6) -> 1 | AB35: =AA35/(1+$B$8)^(Q35-$B$2) -> 0.2357791 | AD35: =AD34+1 -> 2077 | AE35: =1/(1+$B$8)^(L35-$B$2) -> 0.33258971 | AG35: =AG34+1 -> 2087 | AH35: =1/(1+$B$8)^(Q35-$B$2) -> 0.2357791
L36: =L35+1 -> 2078 | M36: =IF($B$17=0,1,MIN($B$16/$B$15,1+(L36-$B$4)*$B$17)) -> 1 | N36: =M36*(1+$B$9)^(L36-$B$2) -> 1.5821677 | O36: =N36/(1+$B$8)^(L36-$B$2) -> 0.50841806 | Q36: =Q35+1 -> 2088 | R36: =IF($B$17=0,1,MIN(1,(1+(Q36-$B$4)*$B$17)/($B$16/$B$15))) -> 1 | S36: =R36*(1+$B$9)^(Q36-$B$2) -> 1.8181599 | T36: =S36/(1+$B$8)^(Q36-$B$2) -> 0.41418753 | V36: =V35+1 -> 2078 | W36: =(1+$B$24)^(L36-$B$4) -> 1 | X36: =W36/(1+$B$8)^(L36-$B$2) -> 0.32134271 | Z36: =Z35+1 -> 2088 | AA36: =(1+$B$24)^(Q36-$B$6) -> 1 | AB36: =AA36/(1+$B$8)^(Q36-$B$2) -> 0.2278059 | AD36: =AD35+1 -> 2078 | AE36: =1/(1+$B$8)^(L36-$B$2) -> 0.32134271 | AG36: =AG35+1 -> 2088 | AH36: =1/(1+$B$8)^(Q36-$B$2) -> 0.2278059
L37: =L36+1 -> 2079 | M37: =IF($B$17=0,1,MIN($B$16/$B$15,1+(L37-$B$4)*$B$17)) -> 1 | N37: =M37*(1+$B$9)^(L37-$B$2) -> 1.6043181 | O37: =N37/(1+$B$8)^(L37-$B$2) -> 0.49810233 | Q37: =Q36+1 -> 2089 | R37: =IF($B$17=0,1,MIN(1,(1+(Q37-$B$4)*$B$17)/($B$16/$B$15))) -> 1 | S37: =R37*(1+$B$9)^(Q37-$B$2) -> 1.8436141 | T37: =S37/(1+$B$8)^(Q37-$B$2) -> 0.40578373 | V37: =V36+1 -> 2079 | W37: =(1+$B$24)^(L37-$B$4) -> 1 | X37: =W37/(1+$B$8)^(L37-$B$2) -> 0.31047605 | Z37: =Z36+1 -> 2089 | AA37: =(1+$B$24)^(Q37-$B$6) -> 1 | AB37: =AA37/(1+$B$8)^(Q37-$B$2) -> 0.22010231 | AD37: =AD36+1 -> 2079 | AE37: =1/(1+$B$8)^(L37-$B$2) -> 0.31047605 | AG37: =AG36+1 -> 2089 | AH37: =1/(1+$B$8)^(Q37-$B$2) -> 0.22010231
L38: =L37+1 -> 2080 | M38: =IF($B$17=0,1,MIN($B$16/$B$15,1+(L38-$B$4)*$B$17)) -> 1 | N38: =M38*(1+$B$9)^(L38-$B$2) -> 1.6267785 | O38: =N38/(1+$B$8)^(L38-$B$2) -> 0.48799591 | Q38: =Q37+1 -> 2090 | R38: =IF($B$17=0,1,MIN(1,(1+(Q38-$B$4)*$B$17)/($B$16/$B$15))) -> 1 | S38: =R38*(1+$B$9)^(Q38-$B$2) -> 1.8694247 | T38: =S38/(1+$B$8)^(Q38-$B$2) -> 0.39755044 | V38: =V37+1 -> 2080 | W38: =(1+$B$24)^(L38-$B$4) -> 1 | X38: =W38/(1+$B$8)^(L38-$B$2) -> 0.29997686 | Z38: =Z37+1 -> 2090 | AA38: =(1+$B$24)^(Q38-$B$6) -> 1 | AB38: =AA38/(1+$B$8)^(Q38-$B$2) -> 0.21265924 | AD38: =AD37+1 -> 2080 | AE38: =1/(1+$B$8)^(L38-$B$2) -> 0.29997686 | AG38: =AG37+1 -> 2090 | AH38: =1/(1+$B$8)^(Q38-$B$2) -> 0.21265924
L39: =L38+1 -> 2081 | M39: =IF($B$17=0,1,MIN($B$16/$B$15,1+(L39-$B$4)*$B$17)) -> 1 | N39: =M39*(1+$B$9)^(L39-$B$2) -> 1.6495534 | O39: =N39/(1+$B$8)^(L39-$B$2) -> 0.47809454 | Q39: =Q38+1 -> 2091 | R39: =IF($B$17=0,1,MIN(1,(1+(Q39-$B$4)*$B$17)/($B$16/$B$15))) -> 1 | S39: =R39*(1+$B$9)^(Q39-$B$2) -> 1.8955966 | T39: =S39/(1+$B$8)^(Q39-$B$2) -> 0.3894842 | V39: =V38+1 -> 2081 | W39: =(1+$B$24)^(L39-$B$4) -> 1 | X39: =W39/(1+$B$8)^(L39-$B$2) -> 0.28983272 | Z39: =Z38+1 -> 2091 | AA39: =(1+$B$24)^(Q39-$B$6) -> 1 | AB39: =AA39/(1+$B$8)^(Q39-$B$2) -> 0.20546787 | AD39: =AD38+1 -> 2081 | AE39: =1/(1+$B$8)^(L39-$B$2) -> 0.28983272 | AG39: =AG38+1 -> 2091 | AH39: =1/(1+$B$8)^(Q39-$B$2) -> 0.20546787
L40: =L39+1 -> 2082 | M40: =IF($B$17=0,1,MIN($B$16/$B$15,1+(L40-$B$4)*$B$17)) -> 1 | N40: =M40*(1+$B$9)^(L40-$B$2) -> 1.6726472 | O40: =N40/(1+$B$8)^(L40-$B$2) -> 0.46839407 | Q40: =Q39+1 -> 2092 | R40: =IF($B$17=0,1,MIN(1,(1+(Q40-$B$4)*$B$17)/($B$16/$B$15))) -> 1 | S40: =R40*(1+$B$9)^(Q40-$B$2) -> 1.922135 | T40: =S40/(1+$B$8)^(Q40-$B$2) -> 0.38158162 | V40: =V39+1 -> 2082 | W40: =(1+$B$24)^(L40-$B$4) -> 1 | X40: =W40/(1+$B$8)^(L40-$B$2) -> 0.28003161 | Z40: =Z39+1 -> 2092 | AA40: =(1+$B$24)^(Q40-$B$6) -> 1 | AB40: =AA40/(1+$B$8)^(Q40-$B$2) -> 0.19851968 | AD40: =AD39+1 -> 2082 | AE40: =1/(1+$B$8)^(L40-$B$2) -> 0.28003161 | AG40: =AG39+1 -> 2092 | AH40: =1/(1+$B$8)^(Q40-$B$2) -> 0.19851968
...

Sheet Liukuvat yksikkoarvot
A1: Matka-aikasäästöt
A2: Auto | B2: 2022 | C2: =B2+1 -> 2023 | D2: =C2+1 -> 2024 | E2: =D2+1 -> 2025 | F2: =E2+1 -> 2026 | G2: =F2+1 -> 2027 | H2: =G2+1 -> 2028 | I2: =H2+1 -> 2029 | J2: =I2+1 -> 2030 | ... AN2: =AM2+1 -> 2060
A3: Työssäkäyntimatka | B3: 9.18 | C3: 9.32 | D3: 9.46 | E3: 9.6 | F3: 9.74 | G3: 9.88 | H3: 10.02 | I3: 10.16 | J3: 10.3 | K3: 10.45 | L3: 10.6 | M3: 10.75 | N3: 10.9 | O3: 11.05 | P3: 11.2 | Q3: 11.35 | R3: 11.5 | S3: 11.65 | T3: 11.8 | U3: 11.97 | V3: 12.14 | W3: 12.31 | X3: 12.48 | Y3: 12.65 | Z3: 12.82 | AA3: 12.99 | AB3: 13.16 | AC3: 13.33 | AD3: 13.5 | AE3: 13.71 | AF3: 13.92 | AG3: 14.13 | AH3: 14.34 | AI3: 14.55 | AJ3: 14.76 | AK3: 14.97 | AL3: 15.18 | AM3: 15.39 | AN3: 15.6
A4: Vapaa-ajan matka | B4: 6.22 | C4: 6.3175 | D4: 6.415 | E4: 6.5125 | F4: 6.61 | G4: 6.7075 | H4: 6.805 | I4: 6.9025 | J4: 7 | K4: 7.1 | L4: 7.2 | M4: 7.3 | N4: 7.4 | O4: 7.5 | P4: 7.6 | Q4: 7.7 | R4: 7.8 | S4: 7.9 | T4: 8 | U4: 8.12 | V4: 8.24 | W4: 8.36 | X4: 8.48 | Y4: 8.6 | Z4: 8.72 | AA4: 8.84 | AB4: 8.96 | AC4: 9.08 | AD4: 9.2 | AE4: 9.33 | AF4: 9.46 | AG4: 9.59 | AH4: 9.72 | AI4: 9.85 | AJ4: 9.98 | AK4: 10.11 | AL4: 10.24 | AM4: 10.37 | AN4: 10.5
A5: Työasiamatka | B5: 27.02 | C5: 27.4175 | D5: 27.815 | E5: 28.2125 | F5: 28.61 | G5: 29.0075 | H5: 29.405 | I5: 29.8025 | J5: 30.2 | K5: 30.65 | L5: 31.1 | M5: 31.55 | N5: 32 | O5: 32.45 | P5: 32.9 | Q5: 33.35 | R5: 33.8 | S5: 34.25 | T5: 34.7 | U5: 35.22 | V5: 35.74 | W5: 36.26 | X5: 36.78 | Y5: 37.3 | Z5: 37.82 | AA5: 38.34 | AB5: 38.86 | AC5: 39.38 | AD5: 39.9 | AE5: 40.49 | AF5: 41.08 | AG5: 41.67 | AH5: 42.26 | AI5: 42.85 | AJ5: 43.44 | AK5: 44.03 | AL5: 44.62 | AM5: 45.21 | AN5: 45.8
A6: Kuorma-auto | B6: 42.24 | C6: 42.28125 | D6: 42.3225 | E6: 42.36375 | F6: 42.405 | G6: 42.44625 | H6: 42.4875 | I6: 42.52875 | J6: 42.57 | K6: 42.616 | L6: 42.662 | M6: 42.708 | N6: 42.754 | O6: 42.8 | P6: 42.846 | Q6: 42.892 | R6: 42.938 | S6: 42.984 | T6: 43.03 | U6: 43.084 | V6: 43.138 | W6: 43.192 | X6: 43.246 | Y6: 43.3 | Z6: 43.354 | AA6: 43.408 | AB6: 43.462 | AC6: 43.516 | AD6: 43.57 | AE6: 43.631 | AF6: 43.692 | AG6: 43.753 | AH6: 43.814 | AI6: 43.875 | AJ6: 43.936 | AK6: 43.997 | AL6: 44.058 | AM6: 44.119 | AN6: 44.18
A7: Yhdistelmä | B7: 60.59 | C7: 60.87375 | D7: 61.1575 | E7: 61.44125 | F7: 61.725 | G7: 62.00875 | H7: 62.2925 | I7: 62.57625 | J7: 62.86 | K7: 63.18 | L7: 63.5 | M7: 63.82 | N7: 64.14 | O7: 64.46 | P7: 64.78 | Q7: 65.1 | R7: 65.42 | S7: 65.74 | T7: 66.06 | U7: 66.429 | V7: 66.798 | W7: 67.167 | X7: 67.536 | Y7: 67.905 | Z7: 68.274 | AA7: 68.643 | AB7: 69.012 | AC7: 69.381 | AD7: 69.75 | AE7: 70.173 | AF7: 70.596 | AG7: 71.019 | AH7: 71.442 | AI7: 71.865 | AJ7: 72.288 | AK7: 72.711 | AL7: 73.134 | AM7: 73.557 | AN7: 73.98
A9: Joukkoliikenne (juna) | B9: 2022 | C9: =B9+1 -> 2023 | D9: =C9+1 -> 2024 | E9: =D9+1 -> 2025 | F9: =E9+1 -> 2026 | G9: =F9+1 -> 2027 | H9: =G9+1 -> 2028 | I9: =H9+1 -> 2029 | J9: =I9+1 -> 2030 | ... AN9: =AM9+1 -> 2060
A10: Työssäkäyntimatka | B10: 7.3 | C10: 7.4125 | D10: 7.525 | E10: 7.6375 | F10: 7.75 | G10: 7.8625 | H10: 7.975 | I10: 8.0875 | J10: 8.2 | K10: 8.32 | L10: 8.44 | M10: 8.56 | N10: 8.68 | O10: 8.8 | P10: 8.92 | Q10: 9.04 | R10: 9.16 | S10: 9.28 | T10: 9.4 | U10: 9.54 | V10: 9.68 | W10: 9.82 | X10: 9.96 | Y10: 10.1 | Z10: 10.24 | AA10: 10.38 | AB10: 10.52 | AC10: 10.66 | AD10: 10.8 | AE10: 10.96 | AF10: 11.12 | AG10: 11.28 | AH10: 11.44 | AI10: 11.6 | AJ10: 11.76 | AK10: 11.92 | AL10: 12.08 | AM10: 12.24 | AN10: 12.4
A11: Vapaa-ajan matka | B11: 5.6 | C11: 5.6875 | D11: 5.775 | E11: 5.8625 | F11: 5.95 | G11: 6.0375 | H11: 6.125 | I11: 6.2125 | J11: 6.3 | K11: 6.39 | L11: 6.48 | M11: 6.57 | N11: 6.66 | O11: 6.75 | P11: 6.84 | Q11: 6.93 | R11: 7.02 | S11: 7.11 | T11: 7.2 | U11: 7.31 | V11: 7.42 | W11: 7.53 | X11: 7.64 | Y11: 7.75 | Z11: 7.86 | AA11: 7.97 | AB11: 8.08 | AC11: 8.19 | AD11: 8.3 | AE11: 8.42 | AF11: 8.54 | AG11: 8.66 | AH11: 8.78 | AI11: 8.9 | AJ11: 9.02 | AK11: 9.14 | AL11: 9.26 | AM11: 9.38 | AN11: 9.5
A12: Työasiamatka | B12: 22.95 | C12: 23.28125 | D12: 23.6125 | E12: 23.94375 | F12: 24.275 | G12: 24.60625 | H12: 24.9375 | I12: 25.26875 | J12: 25.6 | K12: 26 | L12: 26.4 | M12: 26.8 | N12: 27.2 | O12: 27.6 | P12: 28 | Q12: 28.4 | R12: 28.8 | S12: 29.2 | T12: 29.6 | U12: 30.03 | V12: 30.46 | W12: 30.89 | X12: 31.32 | Y12: 31.75 | Z12: 32.18 | AA12: 32.61 | AB12: 33.04 | AC12: 33.47 | AD12: 33.9 | AE12: 34.4 | AF12: 34.9 | AG12: 35.4 | AH12: 35.9 | AI12: 36.4 | AJ12: 36.9 | AK12: 37.4 | AL12: 37.9 | AM12: 38.4 | AN12: 38.9
A14: Polkupyörä | B14: 2022 | C14: =B14+1 -> 2023 | D14: =C14+1 -> 2024 | E14: =D14+1 -> 2025 | F14: =E14+1 -> 2026 | G14: =F14+1 -> 2027 | H14: =G14+1 -> 2028 | I14: =H14+1 -> 2029 | J14: =I14+1 -> 2030 | ... AN14: =AM14+1 -> 2060
A15: Työssäkäyntimatka | C15: 14.230068 | D15: 14.429289 | E15: 14.6313 | F15: 14.836138 | G15: 15.043844 | H15: 15.254457 | I15: 15.46802 | J15: 15.684572 | K15: 15.904156 | L15: 16.126814 | M15: 16.35259 | N15: 16.581526 | O15: 16.813667 | P15: 17.049059 | Q15: 17.287745 | R15: 17.529774 | S15: 17.775191 | T15: 18.024043 | U15: 18.27638 | V15: 18.532249 | W15: 18.791701 | X15: 19.054785 | Y15: 19.321552 | Z15: 19.592053 | AA15: 19.866342 | AB15: 20.144471 | AC15: 20.426494 | AD15: 20.712464 | AE15: 21.002439 | AF15: 21.296473 | AG15: 21.594624 | AH15: 21.896948 | AI15: 22.203506 | AJ15: 22.514355 | AK15: 22.829556 | AL15: 23.14917 | AM15: 23.473258 | AN15: 23.801884
A16: Vapaa-ajan matka | C16: 14.230068 | D16: 14.429289 | E16: 14.6313 | F16: 14.836138 | G16: 15.043844 | H16: 15.254457 | I16: 15.46802 | J16: 15.684572 | K16: 15.904156 | L16: 16.126814 | M16: 16.35259 | N16: 16.581526 | O16: 16.813667 | P16: 17.049059 | Q16: 17.287745 | R16: 17.529774 | S16: 17.775191 | T16: 18.024043 | U16: 18.27638 | V16: 18.532249 | W16: 18.791701 | X16: 19.054785 | Y16: 19.321552 | Z16: 19.592053 | AA16: 19.866342 | AB16: 20.144471 | AC16: 20.426494 | AD16: 20.712464 | AE16: 21.002439 | AF16: 21.296473 | AG16: 21.594624 | AH16: 21.896948 | AI16: 22.203506 | AJ16: 22.514355 | AK16: 22.829556 | AL16: 23.14917 | AM16: 23.473258 | AN16: 23.801884
A17: Työasiamatka | C17: 14.230068 | D17: 14.429289 | E17: 14.6313 | F17: 14.836138 | G17: 15.043844 | H17: 15.254457 | I17: 15.46802 | J17: 15.684572 | K17: 15.904156 | L17: 16.126814 | M17: 16.35259 | N17: 16.581526 | O17: 16.813667 | P17: 17.049059 | Q17: 17.287745 | R17: 17.529774 | S17: 17.775191 | T17: 18.024043 | U17: 18.27638 | V17: 18.532249 | W17: 18.791701 | X17: 19.054785 | Y17: 19.321552 | Z17: 19.592053 | AA17: 19.866342 | AB17: 20.144471 | AC17: 20.426494 | AD17: 20.712464 | AE17: 21.002439 | AF17: 21.296473 | AG17: 21.594624 | AH17: 21.896948 | AI17: 22.203506 | AJ17: 22.514355 | AK17: 22.829556 | AL17: 23.14917 | AM17: 23.473258 | AN17: 23.801884
A19: Ajoneuvokustannus
A20: Vuosi | B20: 2022 | C20: =B20+1 -> 2023 | D20: =C20+1 -> 2024 | E20: =D20+1 -> 2025 | F20: =E20+1 -> 2026 | G20: =F20+1 -> 2027 | H20: =G20+1 -> 2028 | I20: =H20+1 -> 2029 | J20: =I20+1 -> 2030 | ... AN20: =AM20+1 -> 2060
A21: Henkilöauto/Veroton | B21: 0.117 | C21: 0.11675 | D21: 0.1165 | E21: 0.11625 | F21: 0.116 | G21: 0.11575 | H21: 0.1155 | I21: 0.11525 | J21: 0.115 | K21: 0.1122 | L21: 0.1094 | M21: 0.1066 | N21: 0.1038 | O21: 0.101 | P21: 0.0982 | Q21: 0.0954 | R21: 0.0926 | S21: 0.0898 | T21: 0.087 | U21: 0.0861 | V21: 0.0852 | W21: 0.0843 | X21: 0.0834 | Y21: 0.0825 | Z21: 0.0816 | AA21: 0.0807 | AB21: 0.0798 | AC21: 0.0789 | AD21: 0.078 | AE21: 0.0778 | AF21: 0.0776 | AG21: 0.0774 | AH21: 0.0772 | AI21: 0.077 | AJ21: 0.0768 | AK21: 0.0766 | AL21: 0.0764 | AM21: 0.0762 | AN21: 0.076
A22: Henkilöauto/Vero | B22: 0.075 | C22: 0.072875 | D22: 0.07075 | E22: 0.068625 | F22: 0.0665 | G22: 0.064375 | H22: 0.06225 | I22: 0.060125 | J22: 0.058 | K22: 0.0556 | L22: 0.0532 | M22: 0.0508 | N22: 0.0484 | O22: 0.046 | P22: 0.0436 | Q22: 0.0412 | R22: 0.0388 | S22: 0.0364 | T22: 0.034 | U22: 0.0332 | V22: 0.0324 | W22: 0.0316 | X22: 0.0308 | Y22: 0.03 | Z22: 0.0292 | AA22: 0.0284 | AB22: 0.0276 | AC22: 0.0268 | AD22: 0.026 | AE22: 0.0258 | AF22: 0.0256 | AG22: 0.0254 | AH22: 0.0252 | AI22: 0.025 | AJ22: 0.0248 | AK22: 0.0246 | AL22: 0.0244 | AM22: 0.0242 | AN22: 0.024
A23: Henkilöauto/Yhteensä | B23: 0.192 | C23: 0.189625 | D23: 0.18725 | E23: 0.184875 | F23: 0.1825 | G23: 0.180125 | H23: 0.17775 | I23: 0.175375 | J23: 0.173 | K23: 0.1678 | L23: 0.1626 | M23: 0.1574 | N23: 0.1522 | O23: 0.147 | P23: 0.1418 | Q23: 0.1366 | R23: 0.1314 | S23: 0.1262 | T23: 0.121 | U23: 0.1193 | V23: 0.1176 | W23: 0.1159 | X23: 0.1142 | Y23: 0.1125 | Z23: 0.1108 | AA23: 0.1091 | AB23: 0.1074 | AC23: 0.1057 | AD23: 0.104 | AE23: 0.1036 | AF23: 0.1032 | AG23: 0.1028 | AH23: 0.1024 | AI23: 0.102 | AJ23: 0.1016 | AK23: 0.1012 | AL23: 0.1008 | AM23: 0.1004 | AN23: 0.1
A24: Pakettiauto/Veroton | B24: 0.15 | C24: 0.150875 | D24: 0.15175 | E24: 0.152625 | F24: 0.1535 | G24: 0.154375 | H24: 0.15525 | I24: 0.156125 | J24: 0.157 | K24: 0.1523 | L24: 0.1476 | M24: 0.1429 | N24: 0.1382 | O24: 0.1335 | P24: 0.1288 | Q24: 0.1241 | R24: 0.1194 | S24: 0.1147 | T24: 0.11 | U24: 0.1075 | V24: 0.105 | W24: 0.1025 | X24: 0.1 | Y24: 0.0975 | Z24: 0.095 | AA24: 0.0925 | AB24: 0.09 | AC24: 0.0875 | AD24: 0.085 | AE24: 0.0844 | AF24: 0.0838 | AG24: 0.0832 | AH24: 0.0826 | AI24: 0.082 | AJ24: 0.0814 | AK24: 0.0808 | AL24: 0.0802 | AM24: 0.0796 | AN24: 0.079
A25: Pakettiauto/Vero | B25: 0.072 | C25: 0.0705 | D25: 0.069 | E25: 0.0675 | F25: 0.066 | G25: 0.0645 | H25: 0.063 | I25: 0.0615 | J25: 0.06 | K25: 0.0573 | L25: 0.0546 | M25: 0.0519 | N25: 0.0492 | O25: 0.0465 | P25: 0.0438 | Q25: 0.0411 | R25: 0.0384 | S25: 0.0357 | T25: 0.033 | U25: 0.0318 | V25: 0.0306 | W25: 0.0294 | X25: 0.0282 | Y25: 0.027 | Z25: 0.0258 | AA25: 0.0246 | AB25: 0.0234 | AC25: 0.0222 | AD25: 0.021 | AE25: 0.0206 | AF25: 0.0202 | AG25: 0.0198 | AH25: 0.0194 | AI25: 0.019 | AJ25: 0.0186 | AK25: 0.0182 | AL25: 0.0178 | AM25: 0.0174 | AN25: 0.017
A26: Pakettiauto/Yhteensä | B26: 0.222 | C26: 0.221375 | D26: 0.22075 | E26: 0.220125 | F26: 0.2195 | G26: 0.218875 | H26: 0.21825 | I26: 0.217625 | J26: 0.217 | K26: 0.2096 | L26: 0.2022 | M26: 0.1948 | N26: 0.1874 | O26: 0.18 | P26: 0.1726 | Q26: 0.1652 | R26: 0.1578 | S26: 0.1504 | T26: 0.143 | U26: 0.1393 | V26: 0.1356 | W26: 0.1319 | X26: 0.1282 | Y26: 0.1245 | Z26: 0.1208 | AA26: 0.1171 | AB26: 0.1134 | AC26: 0.1097 | AD26: 0.106 | AE26: 0.105 | AF26: 0.104 | AG26: 0.103 | AH26: 0.102 | AI26: 0.101 | AJ26: 0.1 | AK26: 0.099 | AL26: 0.098 | AM26: 0.097 | AN26: 0.096
A27: Linja-auto/Veroton | B27: 0.74 | C27: 0.73925 | D27: 0.7385 | E27: 0.73775 | F27: 0.737 | G27: 0.73625 | H27: 0.7355 | I27: 0.73475 | J27: 0.734 | K27: 0.7202 | L27: 0.7064 | M27: 0.6926 | N27: 0.6788 | O27: 0.665 | P27: 0.6512 | Q27: 0.6374 | R27: 0.6236 | S27: 0.6098 | T27: 0.596 | U27: 0.5981 | V27: 0.6002 | W27: 0.6023 | X27: 0.6044 | Y27: 0.6065 | Z27: 0.6086 | AA27: 0.6107 | AB27: 0.6128 | AC27: 0.6149 | AD27: 0.617 | AE27: 0.6238 | AF27: 0.6306 | AG27: 0.6374 | AH27: 0.6442 | AI27: 0.651 | AJ27: 0.6578 | AK27: 0.6646 | AL27: 0.6714 | AM27: 0.6782 | AN27: 0.685
A28: Linja-auto/Vero | B28: 0.188 | C28: 0.180875 | D28: 0.17375 | E28: 0.166625 | F28: 0.1595 | G28: 0.152375 | H28: 0.14525 | I28: 0.138125 | J28: 0.131 | K28: 0.1252 | L28: 0.1194 | M28: 0.1136 | N28: 0.1078 | O28: 0.102 | P28: 0.0962 | Q28: 0.0904 | R28: 0.0846 | S28: 0.0788 | T28: 0.073 | U28: 0.0711 | V28: 0.0692 | W28: 0.0673 | X28: 0.0654 | Y28: 0.0635 | Z28: 0.0616 | AA28: 0.0597 | AB28: 0.0578 | AC28: 0.0559 | AD28: 0.054 | AE28: 0.0531 | AF28: 0.0522 | AG28: 0.0513 | AH28: 0.0504 | AI28: 0.0495 | AJ28: 0.0486 | AK28: 0.0477 | AL28: 0.0468 | AM28: 0.0459 | AN28: 0.045
A29: Linja-auto/Yhteensä | B29: 0.928 | C29: 0.920125 | D29: 0.91225 | E29: 0.904375 | F29: 0.8965 | G29: 0.888625 | H29: 0.88075 | I29: 0.872875 | J29: 0.865 | K29: 0.8454 | L29: 0.8258 | M29: 0.8062 | N29: 0.7866 | O29: 0.767 | P29: 0.7474 | Q29: 0.7278 | R29: 0.7082 | S29: 0.6886 | T29: 0.669 | U29: 0.6692 | V29: 0.6694 | W29: 0.6696 | X29: 0.6698 | Y29: 0.67 | Z29: 0.6702 | AA29: 0.6704 | AB29: 0.6706 | AC29: 0.6708 | AD29: 0.671 | AE29: 0.6769 | AF29: 0.6828 | AG29: 0.6887 | AH29: 0.6946 | AI29: 0.7005 | AJ29: 0.7064 | AK29: 0.7123 | AL29: 0.7182 | AM29: 0.7241 | AN29: 0.73
A30: Kuorma-auto/Veroton | B30: 0.682 | C30: 0.697125 | D30: 0.71225 | E30: 0.727375 | F30: 0.7425 | G30: 0.757625 | H30: 0.77275 | I30: 0.787875 | J30: 0.803 | K30: 0.7965 | L30: 0.79 | M30: 0.7835 | N30: 0.777 | O30: 0.7705 | P30: 0.764 | Q30: 0.7575 | R30: 0.751 | S30: 0.7445 | T30: 0.738 | U30: 0.7329 | V30: 0.7278 | W30: 0.7227 | X30: 0.7176 | Y30: 0.7125 | Z30: 0.7074 | AA30: 0.7023 | AB30: 0.6972 | AC30: 0.6921 | AD30: 0.687 | AE30: 0.6819 | AF30: 0.6768 | AG30: 0.6717 | AH30: 0.6666 | AI30: 0.6615 | AJ30: 0.6564 | AK30: 0.6513 | AL30: 0.6462 | AM30: 0.6411 | AN30: 0.636
A31: Kuorma-auto/Vero | B31: 0.202 | C31: 0.2 | D31: 0.198 | E31: 0.196 | F31: 0.194 | G31: 0.192 | H31: 0.19 | I31: 0.188 | J31: 0.186 | K31: 0.1818 | L31: 0.1776 | M31: 0.1734 | N31: 0.1692 | O31: 0.165 | P31: 0.1608 | Q31: 0.1566 | R31: 0.1524 | S31: 0.1482 | T31: 0.144 | U31: 0.14 | V31: 0.136 | W31: 0.132 | X31: 0.128 | Y31: 0.124 | Z31: 0.12 | AA31: 0.116 | AB31: 0.112 | AC31: 0.108 | AD31: 0.104 | AE31: 0.1007 | AF31: 0.0974 | AG31: 0.0941 | AH31: 0.0908 | AI31: 0.0875 | AJ31: 0.0842 | AK31: 0.0809 | AL31: 0.0776 | AM31: 0.0743 | AN31: 0.071
A32: Kuorma-auto/Yhteensä | B32: 0.884 | C32: 0.897125 | D32: 0.91025 | E32: 0.923375 | F32: 0.9365 | G32: 0.949625 | H32: 0.96275 | I32: 0.975875 | J32: 0.989 | K32: 0.9783 | L32: 0.9676 | M32: 0.9569 | N32: 0.9462 | O32: 0.9355 | P32: 0.9248 | Q32: 0.9141 | R32: 0.9034 | S32: 0.8927 | T32: 0.882 | U32: 0.8729 | V32: 0.8638 | W32: 0.8547 | X32: 0.8456 | Y32: 0.8365 | Z32: 0.8274 | AA32: 0.8183 | AB32: 0.8092 | AC32: 0.8001 | AD32: 0.791 | AE32: 0.7826 | AF32: 0.7742 | AG32: 0.7658 | AH32: 0.7574 | AI32: 0.749 | AJ32: 0.7406 | AK32: 0.7322 | AL32: 0.7238 | AM32: 0.7154 | AN32: 0.707
... A35: Ajoneuvoyhdistelmä/Yhteensä | B35: 1.023 | C35: 1.039125 | D35: 1.05525 | E35: 1.071375 | F35: 1.0875 | G35: 1.103625 | H35: 1.11975 | I35: 1.135875 | J35: 1.152 | K35: 1.1193 | L35: 1.0866 | M35: 1.0539 | N35: 1.0212 | O35: 0.9885 | P35: 0.9558 | Q35: 0.9231 | R35: 0.8904 | S35: 0.8577 | T35: 0.825 | U35: 0.8183 | V35: 0.8116 | W35: 0.8049 | X35: 0.7982 | Y35: 0.7915 | Z35: 0.7848 | AA35: 0.7781 | AB35: 0.7714 | AC35: 0.7647 | AD35: 0.758 | AE35: 0.7535 | AF35: 0.749 | AG35: 0.7445 | AH35: 0.74 | AI35: 0.7355 | AJ35: 0.731 | AK35: 0.7265 | AL35: 0.722 | AM35: 0.7175 | AN35: 0.713
A37: Yksikkökustannukset
A38: Melutaso dB(A) | B38: 2022 | C38: 2023 | D38: 2024 | E38: 2025 | F38: 2026 | G38: 2027 | H38: 2028 | I38: 2029 | J38: 2030 | K38: 2031 | L38: 2032 | M38: 2033 | N38: 2034 | O38: 2035 | P38: 2036 | Q38: 2037 | R38: 2038 | S38: 2039 | T38: 2040 | U38: 2041 | V38: 2042 | W38: 2043 | X38: 2044 | Y38: 2045 | Z38: 2046 | AA38: 2047 | AB38: 2048 | AC38: 2049 | AD38: 2050 | AE38: 2051 | AF38: 2052 | AG38: 2053 | AH38: 2054 | AI38: 2055 | AJ38: 2056 | AK38: 2057 | AL38: 2058 | AM38: 2059 | AN38: 2060
A39: 50-54 | B39: 140 | C39: 142 | D39: 144 | E39: 146 | F39: 148 | G39: 150 | H39: 152 | I39: 154 | J39: 156 | K39: 158.4 | L39: 160.8 | M39: 163.2 | N39: 165.6 | O39: 168 | P39: 170.4 | Q39: 172.8 | R39: 175.2 | S39: 177.6 | T39: 180 | U39: 182.7 | V39: 185.4 | W39: 188.1 | X39: 190.8 | Y39: 193.5 | Z39: 196.2 | AA39: 198.9 | AB39: 201.6 | AC39: 204.3 | AD39: 207 | AE39: 210 | AF39: 213 | AG39: 216 | AH39: 219 | AI39: 222 | AJ39: 225 | AK39: 228 | AL39: 231 | AM39: 234 | AN39: 237
A40: 55-59 | B40: 740 | C40: 750.875 | D40: 761.75 | E40: 772.625 | F40: 783.5 | G40: 794.375 | H40: 805.25 | I40: 816.125 | J40: 827 | K40: 839.3 | L40: 851.6 | M40: 863.9 | N40: 876.2 | O40: 888.5 | P40: 900.8 | Q40: 913.1 | R40: 925.4 | S40: 937.7 | T40: 950 | U40: 964.2 | V40: 978.4 | W40: 992.6 | X40: 1006.8 | Y40: 1021 | Z40: 1035.2 | AA40: 1049.4 | AB40: 1063.6 | AC40: 1077.8 | AD40: 1092 | AE40: 1108.3 | AF40: 1124.6 | AG40: 1140.9 | AH40: 1157.2 | AI40: 1173.5 | AJ40: 1189.8 | AK40: 1206.1 | AL40: 1222.4 | AM40: 1238.7 | AN40: 1255
A41: 60-64 | B41: 1870 | C41: 1897.5 | D41: 1925 | E41: 1952.5 | F41: 1980 | G41: 2007.5 | H41: 2035 | I41: 2062.5 | J41: 2090 | K41: 2121.2 | L41: 2152.4 | M41: 2183.6 | N41: 2214.8 | O41: 2246 | P41: 2277.2 | Q41: 2308.4 | R41: 2339.6 | S41: 2370.8 | T41: 2402 | U41: 2437.8 | V41: 2473.6 | W41: 2509.4 | X41: 2545.2 | Y41: 2581 | Z41: 2616.8 | AA41: 2652.6 | AB41: 2688.4 | AC41: 2724.2 | AD41: 2760 | AE41: 2801.2 | AF41: 2842.4 | AG41: 2883.6 | AH41: 2924.8 | AI41: 2966 | AJ41: 3007.2 | AK41: 3048.4 | AL41: 3089.6 | AM41: 3130.8 | AN41: 3172
A42: 65-69 | B42: 3500 | C42: 3551.5 | D42: 3603 | E42: 3654.5 | F42: 3706 | G42: 3757.5 | H42: 3809 | I42: 3860.5 | J42: 3912 | K42: 3970.3 | L42: 4028.6 | M42: 4086.9 | N42: 4145.2 | O42: 4203.5 | P42: 4261.8 | Q42: 4320.1 | R42: 4378.4 | S42: 4436.7 | T42: 4495 | U42: 4562.1 | V42: 4629.2 | W42: 4696.3 | X42: 4763.4 | Y42: 4830.5 | Z42: 4897.6 | AA42: 4964.7 | AB42: 5031.8 | AC42: 5098.9 | AD42: 5166 | AE42: 5243 | AF42: 5320 | AG42: 5397 | AH42: 5474 | AI42: 5551 | AJ42: 5628 | AK42: 5705 | AL42: 5782 | AM42: 5859 | AN42: 5936
A43: 70-75 | B43: 5900 | C43: 5986.75 | D43: 6073.5 | E43: 6160.25 | F43: 6247 | G43: 6333.75 | H43: 6420.5 | I43: 6507.25 | J43: 6594 | K43: 6692.4 | L43: 6790.8 | M43: 6889.2 | N43: 6987.6 | O43: 7086 | P43: 7184.4 | Q43: 7282.8 | R43: 7381.2 | S43: 7479.6 | T43: 7578 | U43: 7691 | V43: 7804 | W43: 7917 | X43: 8030 | Y43: 8143 | Z43: 8256 | AA43: 8369 | AB43: 8482 | AC43: 8595 | AD43: 8708 | AE43: 8837.9 | AF43: 8967.8 | AG43: 9097.7 | AH43: 9227.6 | AI43: 9357.5 | AJ43: 9487.4 | AK43: 9617.3 | AL43: 9747.2 | AM43: 9877.1 | AN43: 10007
A45: Päästöt / taajama (eur/tonni) | B45: 2022 | C45: 2023 | D45: 2024 | E45: 2025 | F45: 2026 | G45: 2027 | H45: 2028 | I45: 2029 | J45: 2030 | K45: 2031 | L45: 2032 | M45: 2033 | N45: 2034 | O45: 2035 | P45: 2036 | Q45: 2037 | R45: 2038 | S45: 2039 | T45: 2040 | U45: 2041 | V45: 2042 | W45: 2043 | X45: 2044 | Y45: 2045 | Z45: 2046 | AA45: 2047 | AB45: 2048 | AC45: 2049 | AD45: 2050 | AE45: 2051 | AF45: 2052 | AG45: 2053 | AH45: 2054 | AI45: 2055 | AJ45: 2056 | AK45: 2057 | AL45: 2058 | AM45: 2059 | AN45: 2060
A46: NOx | B46: 1664 | C46: 1688.5 | D46: 1713 | E46: 1737.5 | F46: 1762 | G46: 1786.5 | H46: 1811 | I46: 1835.5 | J46: 1860 | K46: 1887.7 | L46: 1915.4 | M46: 1943.1 | N46: 1970.8 | O46: 1998.5 | P46: 2026.2 | Q46: 2053.9 | R46: 2081.6 | S46: 2109.3 | T46: 2137 | U46: 2168.9 | V46: 2200.8 | W46: 2232.7 | X46: 2264.6 | Y46: 2296.5 | Z46: 2328.4 | AA46: 2360.3 | AB46: 2392.2 | AC46: 2424.1 | AD46: 2456 | AE46: 2492.6 | AF46: 2529.2 | AG46: 2565.8 | AH46: 2602.4 | AI46: 2639 | AJ46: 2675.6 | AK46: 2712.2 | AL46: 2748.8 | AM46: 2785.4 | AN46: 2822
A47: PM | B47: 155288 | C47: 157571.5 | D47: 159855 | E47: 162138.5 | F47: 164422 | G47: 166705.5 | H47: 168989 | I47: 171272.5 | J47: 173556 | K47: 176144.8 | L47: 178733.6 | M47: 181322.4 | N47: 183911.2 | O47: 186500 | P47: 189088.8 | Q47: 191677.6 | R47: 194266.4 | S47: 196855.2 | T47: 199444 | U47: 202412.5 | V47: 205381 | W47: 208349.5 | X47: 211318 | Y47: 214286.5 | Z47: 217255 | AA47: 220223.5 | AB47: 223192 | AC47: 226160.5 | AD47: 229129 | AE47: 232553.9 | AF47: 235978.8 | AG47: 239403.7 | AH47: 242828.6 | AI47: 246253.5 | AJ47: 249678.4 | AK47: 253103.3 | AL47: 256528.2 | AM47: 259953.1 | AN47: 263378
...

Sheet Kayttajahyodyt
B1: Aikasäästön arvo | C1: Lähde: Väylävirasto yksikköarvot | H1: Henkilöauton keskikuormitus
A2: =Diskonttaus!B4 -> 2045 | B2: Työssäkäyntimatka | C2: Vapaa-ajan matka | D2: Työasiamatka | E2: Kuorma-auto | F2: Yhdistelmä | H2: Työssäkäyntimatka | I2: Vapaa-ajan matka
A3: Auto | B3: {=IFERROR(_xlfn.SWITCH($A3,"Auto",INDEX('Liukuvat yksikkoarvot'!$B$3:$AN$7,MATCH(B$2,'Liukuvat yksikkoarvot'!$A$3:$A$7,0),MATCH($A$2,'Liukuvat yksikkoarvot'!$B$2:$AN$2,0)),"Joukkoliikenne (juna)",INDEX('Liukuvat yksikkoarvot'!$B$10:$AN$12,MATCH(B$2,'Liukuvat yksikkoarvot'!$A$10:$A$12,0),MATCH($A$2,'Liukuvat yksikkoarvot'!$B$9:$AN$9,0)),"Polkupyörä",INDEX('Liukuvat yksikkoarvot'!$B$15:$AN$17,MATCH(B$2,'Liukuvat yksikkoarvot'!$A$15:$A$17,0),MATCH($A$2,'Liukuvat yksikkoarvot'!$B$14:$AN$14,0)),""),"")} -> 12.65 | C3: {=IFERROR(_xlfn.SWITCH($A3,"Auto",INDEX('Liukuvat yksikkoarvot'!$B$3:$AN$7,MATCH(C$2,'Liukuvat yksikkoarvot'!$A$3:$A$7,0),MATCH($A$2,'Liukuvat yksikkoarvot'!$B$2:$AN$2,0)),"Joukkoliikenne (juna)",INDEX('Liukuvat yksikkoarvot'!$B$10:$AN$12,MATCH(C$2,'Liukuvat yksikkoarvot'!$A$10:$A$12,0),MATCH($A$2,'Liukuvat yksikkoarvot'!$B$9:$AN$9,0)),"Polkupyörä",INDEX('Liukuvat yksikkoarvot'!$B$15:$AN$17,MATCH(C$2,'Liukuvat yksikkoarvot'!$A$15:$A$17,0),MATCH($A$2,'Liukuvat yksikkoarvot'!$B$14:$AN$14,0)),""),"")} -> 8.6 | D3: {=IFERROR(_xlfn.SWITCH($A3,"Auto",INDEX('Liukuvat yksikkoarvot'!$B$3:$AN$7,MATCH(D$2,'Liukuvat yksikkoarvot'!$A$3:$A$7,0),MATCH($A$2,'Liukuvat yksikkoarvot'!$B$2:$AN$2,0)),"Joukkoliikenne (juna)",INDEX('Liukuvat yksikkoarvot'!$B$10:$AN$12,MATCH(D$2,'Liukuvat yksikkoarvot'!$A$10:$A$12,0),MATCH($A$2,'Liukuvat yksikkoarvot'!$B$9:$AN$9,0)),"Polkupyörä",INDEX('Liukuvat yksikkoarvot'!$B$15:$AN$17,MATCH(D$2,'Liukuvat yksikkoarvot'!$A$15:$A$17,0),MATCH($A$2,'Liukuvat yksikkoarvot'!$B$14:$AN$14,0)),""),"")} -> 37.3 | E3: {=IFERROR(_xlfn.SWITCH($A3,"Auto",INDEX('Liukuvat yksikkoarvot'!$B$3:$AN$7,MATCH(E$2,'Liukuvat yksikkoarvot'!$A$3:$A$7,0),MATCH($A$2,'Liukuvat yksikkoarvot'!$B$2:$AN$2,0)),"Joukkoliikenne (juna)",INDEX('Liukuvat yksikkoarvot'!$B$10:$AN$12,MATCH(E$2,'Liukuvat yksikkoarvot'!$A$10:$A$12,0),MATCH($A$2,'Liukuvat yksikkoarvot'!$B$9:$AN$9,0)),"Polkupyörä",INDEX('Liukuvat yksikkoarvot'!$B$15:$AN$17,MATCH(E$2,'Liukuvat yksikkoarvot'!$A$15:$A$17,0),MATCH($A$2,'Liukuvat yksikkoarvot'!$B$14:$AN$14,0)),""),"")} -> 43.3 | F3: {=IFERROR(_xlfn.SWITCH($A3,"Auto",INDEX('Liukuvat yksikkoarvot'!$B$3:$AN$7,MATCH(F$2,'Liukuvat yksikkoarvot'!$A$3:$A$7,0),MATCH($A$2,'Liukuvat yksikkoarvot'!$B$2:$AN$2,0)),"Joukkoliikenne (juna)",INDEX('Liukuvat yksikkoarvot'!$B$10:$AN$12,MATCH(F$2,'Liukuvat yksikkoarvot'!$A$10:$A$12,0),MATCH($A$2,'Liukuvat yksikkoarvot'!$B$9:$AN$9,0)),"Polkupyörä",INDEX('Liukuvat yksikkoarvot'!$B$15:$AN$17,MATCH(F$2,'Liukuvat yksikkoarvot'!$A$15:$A$17,0),MATCH($A$2,'Liukuvat yksikkoarvot'!$B$14:$AN$14,0)),""),"")} -> 67.905 | H3: 1.16 | I3: 1.4
A4: Joukkoliikenne (juna) | B4: {=IFERROR(_xlfn.SWITCH($A4,"Auto",INDEX('Liukuvat yksikkoarvot'!$B$3:$AN$7,MATCH(B$2,'Liukuvat yksikkoarvot'!$A$3:$A$7,0),MATCH($A$2,'Liukuvat yksikkoarvot'!$B$2:$AN$2,0)),"Joukkoliikenne (juna)",INDEX('Liukuvat yksikkoarvot'!$B$10:$AN$12,MATCH(B$2,'Liukuvat yksikkoarvot'!$A$10:$A$12,0),MATCH($A$2,'Liukuvat yksikkoarvot'!$B$9:$AN$9,0)),"Polkupyörä",INDEX('Liukuvat yksikkoarvot'!$B$15:$AN$17,MATCH(B$2,'Liukuvat yksikkoarvot'!$A$15:$A$17,0),MATCH($A$2,'Liukuvat yksikkoarvot'!$B$14:$AN$14,0)),""),"")} -> 10.1 | C4: {=IFERROR(_xlfn.SWITCH($A4,"Auto",INDEX('Liukuvat yksikkoarvot'!$B$3:$AN$7,MATCH(C$2,'Liukuvat yksikkoarvot'!$A$3:$A$7,0),MATCH($A$2,'Liukuvat yksikkoarvot'!$B$2:$AN$2,0)),"Joukkoliikenne (juna)",INDEX('Liukuvat yksikkoarvot'!$B$10:$AN$12,MATCH(C$2,'Liukuvat yksikkoarvot'!$A$10:$A$12,0),MATCH($A$2,'Liukuvat yksikkoarvot'!$B$9:$AN$9,0)),"Polkupyörä",INDEX('Liukuvat yksikkoarvot'!$B$15:$AN$17,MATCH(C$2,'Liukuvat yksikkoarvot'!$A$15:$A$17,0),MATCH($A$2,'Liukuvat yksikkoarvot'!$B$14:$AN$14,0)),""),"")} -> 7.75 | D4: {=IFERROR(_xlfn.SWITCH($A4,"Auto",INDEX('Liukuvat yksikkoarvot'!$B$3:$AN$7,MATCH(D$2,'Liukuvat yksikkoarvot'!$A$3:$A$7,0),MATCH($A$2,'Liukuvat yksikkoarvot'!$B$2:$AN$2,0)),"Joukkoliikenne (juna)",INDEX('Liukuvat yksikkoarvot'!$B$10:$AN$12,MATCH(D$2,'Liukuvat yksikkoarvot'!$A$10:$A$12,0),MATCH($A$2,'Liukuvat yksikkoarvot'!$B$9:$AN$9,0)),"Polkupyörä",INDEX('Liukuvat yksikkoarvot'!$B$15:$AN$17,MATCH(D$2,'Liukuvat yksikkoarvot'!$A$15:$A$17,0),MATCH($A$2,'Liukuvat yksikkoarvot'!$B$14:$AN$14,0)),""),"")} -> 31.75 | E4: {=IFERROR(_xlfn.SWITCH($A4,"Auto",INDEX('Liukuvat yksikkoarvot'!$B$3:$AN$7,MATCH(E$2,'Liukuvat yksikkoarvot'!$A$3:$A$7,0),MATCH($A$2,'Liukuvat yksikkoarvot'!$B$2:$AN$2,0)),"Joukkoliikenne (juna)",INDEX('Liukuvat yksikkoarvot'!$B$10:$AN$12,MATCH(E$2,'Liukuvat yksikkoarvot'!$A$10:$A$12,0),MATCH($A$2,'Liukuvat yksikkoarvot'!$B$9:$AN$9,0)),"Polkupyörä",INDEX('Liukuvat yksikkoarvot'!$B$15:$AN$17,MATCH(E$2,'Liukuvat yksikkoarvot'!$A$15:$A$17,0),MATCH($A$2,'Liukuvat yksikkoarvot'!$B$14:$AN$14,0)),""),"")} | F4: {=IFERROR(_xlfn.SWITCH($A4,"Auto",INDEX('Liukuvat yksikkoarvot'!$B$3:$AN$7,MATCH(F$2,'Liukuvat yksikkoarvot'!$A$3:$A$7,0),MATCH($A$2,'Liukuvat yksikkoarvot'!$B$2:$AN$2,0)),"Joukkoliikenne (juna)",INDEX('Liukuvat yksikkoarvot'!$B$10:$AN$12,MATCH(F$2,'Liukuvat yksikkoarvot'!$A$10:$A$12,0),MATCH($A$2,'Liukuvat yksikkoarvot'!$B$9:$AN$9,0)),"Polkupyörä",INDEX('Liukuvat yksikkoarvot'!$B$15:$AN$17,MATCH(F$2,'Liukuvat yksikkoarvot'!$A$15:$A$17,0),MATCH($A$2,'Liukuvat yksikkoarvot'!$B$14:$AN$14,0)),""),"")}
